Workbook

Sheet 25공연
C2: 2025 공연사업 운영 결과
B3: 구분 | Q3: (단위 : 천원)
D4: 진행월 | E4: 횟수 | F4: 예산 | G4: 지출 | I4: 판매 수수료 | J4: 매출 | L4: 차액 (a-b) | M4: 인원수 | P4: 수익율 | Q4: 수익율
G5: 전표실적(a) | H5: 비율 | J5: 정산서(b) | K5: 비율 | M5: 판매 | N5: 초대 | O5: 계
B6: 예 술 성 | C6: 신년음악회 | D6: 1월 | E6: 1 | F6: 45500000 | G6: 45208740 | H6: =SUM(G6/G23*100) | I6: 743474 | J6: 23108000 | K6: =SUM(J6/J23*100) | L6: =SUM(J6-G6) | M6: 464 | N6: 40 | O6: =SUM(M6:N6) | P6: =J6/(G6+I6)*100 | Q6: =Q25 | R6: 브런치 1 | S6: 8526000 | T6: 546 | U6: 26 | V6: =SUM(T6:U6)
C7: 클래식 시리즈1(백건우와 모차르트) | D7: 3월 | E7: 1 | F7: 40500000 | G7: 40223740 | H7: =SUM(G7/G23*100) | I7: 1123227 | J7: 31545000 | K7: =SUM(J7/J23*100) | L7: =SUM(J7-G7) | M7: 815 | N7: 10 | O7: =SUM(M7:N7) | P7: =J7/(G7+I7)*100 | R7: 브런치 2 | S7: 10045500 | T7: 691 | U7: 32 | V7: =SUM(T7:U7)
C8: 협력사업2(아파나도르) | D8: 4월 | E8: 2 | F8: 276000000 | G8: 275842232 | H8: =SUM(G8/G23*100) | I8: 1470249 | J8: 42609000 | K8: =SUM(J8/J23*100) | L8: =SUM(J8-G8) | M8: 546 | N8: 211 | O8: =SUM(M8:N8) | P8: =J8/(G8+I8)*100
C9: 공모사업(창작발레갓,꽃의비밀,쇼팽) | D9: 5/7/9월 | E9: 4 | F9: 26480000 | G9: =SUM(G30:G32) | H9: =SUM(G9/G23*100) | I9: =SUM(I30:I32) | J9: =SUM(J30:J32) | K9: =SUM(J9/J23*100) | L9: =SUM(J9-G9) | M9: =SUM(M30:M32) | N9: =SUM(N30:N32) | O9: =SUM(M9:N9) | P9: =J9/(G9+I9)*100 | R9: 브런치 3 | S9: 9974000 | T9: 718 | U9: 10 | V9: =SUM(T9:U9)
C10: 문화나눔콘서트(예울마루 위크) | D10: 5월 | E10: 1 | F10: 118020000 | G10: 117953320 | H10: =SUM(G10/G23*100) | I10: 0 | J10: 0 | K10: =SUM(J10/J23*100) | L10: =SUM(J10-G10) | M10: 0 | N10: 900 | O10: =SUM(M10:N10) | P10: =J10/(G10+I10)*100
C11: 헬로 시리즈 | D11: 11월 | E11: 1 | F11: 63000000 | G11: 61660580 | H11: =SUM(G11/G23*100) | I11: 249194 | J11: 9073000 | K11: =SUM(J11/J23*100) | L11: =SUM(J11-G11) | M11: 428 | N11: 30 | O11: =SUM(M11:N11) | P11: =J11/(G11+I11)*100 | R11: 브런치 4 | S11: 12922500 | T11: 921 | U11: 16 | V11: =SUM(T11:U11)
C12: 클래식시리즈2(실내악 페스티벌) | D12: 10월 | E12: 5 | F12: 150500000 | G12: 149504000 | H12: =SUM(G12/G23*100) | I12: 662288 | J12: 21688000 | K12: =SUM(J12/J23*100) | L12: =SUM(J12-G12) | M12: 1038 | N12: 294 | O12: =SUM(M12:N12) | P12: =J12/(G12+I12)*100 | S12: =SUM(S6:S11) | T12: =SUM(T6:T11) | U12: =SUM(U6:U11) | V12: =SUM(V6:V11)
C13: 연극(내일은 내일에게, 청소년) | D13: 11월 | E13: 6회 | F13: 43000000 | G13: 42096540 | H13: =SUM(G13/G23*100) | I13: 3560239 | J13: 107707500 | K13: =SUM(J13/J23*100) | L13: =SUM(J13-G13) | M13: 3568 | N13: 155 | O13: =SUM(M13:N13) | P13: =J13/(G13+I13)*100 | R13: 실내악 2 | S13: 4219000 | T13: 140 | U13: 72 | V13: =SUM(T13:U13)
C14: 크리스마스 1(발레-호두까기인형) | D14: 12월 | E14: 2회 | F14: 50500000 | G14: 44196540 | H14: =SUM(G14/G25*100) | I14: 1635045 | J14: 44200750 | K14: =SUM(J14/J25*100) | L14: =J14-G14 | M14: 1408 | N14: 34 | O14: =SUM(M14:N14) | P14: =J14/(G14+I14)*100 | R14: 실내악 1 | S14: 9331000 | T14: 333 | U14: 346 | V14: =SUM(T14:U14)
C15: 브런치 콘서트 | D15: 3/5/7/9/12월 | E15: 5 | F15: 44000000 | G15: =G41 | H15: =SUM(G15/G23*100) | I15: =I41 | J15: =J41 | K15: =SUM(J15/J23*100) | L15: =SUM(J15-G15) | M15: =M41 | N15: =N41 | O15: =SUM(M15:N15) | P15: =J15/(G15+I15)*100
B16: 상 업 성 | C16: 아동극시리즈1 (넌 특별하단다) | D16: 5월 | E16: 10 | F16: 63500000 | G16: 62586320 | H16: =SUM(G16/G23*100) | I16: 3014220 | J16: 89778000 | K16: =SUM(J16/J23*100) | L16: =SUM(J16-G16) | M16: 2756 | N16: 97 | O16: =SUM(M16:N16) | P16: =J16/(G16+I16)*100 | Q16: =Q26
C17: 뮤지컬1(명성황후) | D17: 6월 | E17: 4 | F17: 176000000 | G17: 175988780 | H17: =SUM(G17/G23*100) | I17: 9221140 | J17: 247663250 | K17: =SUM(J17/J23*100) | L17: =SUM(J17-G17) | M17: 3636 | N17: 45 | O17: =SUM(M17:N17) | P17: =J17/(G17+I17)*100
C18: 아동극시리즈2 (넘버블록스) | D18: 8월 | E18: 6 | F18: 6000000 | G18: 5053160 | H18: =SUM(G18/G23*100) | I18: 5465688 | J18: 15981731 | K18: =SUM(J18/J23*100) | L18: =SUM(J18-G18) | M18: 2921 | N18: 79 | O18: =SUM(M18:N18) | P18: =J18/(G18+I18)*100
C19: 아동극시리즈3(설민석의한국사대모험) | D19: 9월 | E19: 6회 | F19: 71500000 | G19: 71270940 | H19: =SUM(G19/G23*100) | I19: 3927586 | J19: 113412200 | K19: =SUM(J19/J23*100) | L19: =SUM(J19-G19) | M19: 3042 | N19: 136 | O19: =SUM(M19:N19) | P19: =J19/(G19+I19)*100
C20: 협력사업1(뮤지컬 시카고) | D20: 2월 | E20: 4 | F20: 10100000 | G20: 10082720 | H20: =SUM(G20/G23*100) | I20: 2212220 | J20: 52751000 | K20: =SUM(J20/J23*100) | L20: =SUM(J20-G20) | M20: 3808 | N20: 76 | O20: =SUM(M20:N20) | P20: =J20/(G20+I20)*100
C21: 뮤지컬2 (킹키부츠) | D21: 11월 | E21: 4 | F21: 197900000 | G21: 196748440 | H21: =SUM(G21/G23*100) | I21: 10107530 | J21: 242499500 | K21: =SUM(J21/J23*100) | L21: =SUM(J21-G21) | M21: 3280 | N21: 30 | O21: =SUM(M21:N21) | P21: =J21/(G21+I21)*100 | R21: 무풍 | S21: 5000000 | T21: 548 | U21: 9 | V21: =SUM(T21:U21)
C22: 청소년뮤지컬 (김종욱찾기) | D22: 12월 | E22: 10회 | F22: 55500000 | G22: 54444400 | H22: =SUM(G22/G23*100) | I22: 2828843 | J22: 104732500 | K22: =SUM(J22/J23*100) | L22: =SUM(J22-G22) | M22: 2732 | N22: 68 | O22: =SUM(M22:N22) | P22: =J22/(G22+I22)*100
B23: 합계 | E23: =SUM(E6:E22) | F23: =SUM(F6:F22) | G23: =SUM(G6:G22) | H23: =SUM(H6:H22) | I23: =SUM(I6:I22) | J23: =SUM(J6:J22) | K23: =SUM(K6:K22) | L23: =SUM(L6:L22) | ... O23: =SUM(O6:O22) | P23: =J23/(G23+I23)*100 | Q23: =J23/(G23+I23)*100
G25: =SUM(G6:G14) | I25: =SUM(I6:I14) | J25: =SUM(J6:J14) | Q25: =(J25/(G25+I25))*100
G26: =SUM(G16:G22) | I26: =SUM(I16:I22) | J26: =SUM(J16:J22) | Q26: =(J26/(G26+I26))*100
B28: 구분 | D28: 진행월 | E28: 횟수 | F28: 예산 | G28: 지출 | I28: 판매 수수료 | J28: 매출 | L28: 차액 (a-b) | M28: 인원수 | P28: 수익율 | Q28: 수익율
G29: 전표실적(a) | H29: 비율 | J29: 정산서(b) | K29: 비율 | M29: 판매 | N29: 초대 | O29: 계
C30: 공모사업-창작발레갓 | D30: 5월 | E30: 1 | F30: 4150000 | G30: 4150000 | H30: =SUM(G30/F30*100) | I30: 625790 | J30: 15038000 | K30: =SUM(J30/J45*100) | L30: =SUM(J30-G30) | M30: 638 | N30: 16 | O30: =SUM(M30:N30) | P30: =J30/(G30+I30)*100 | Q30: =AVERAGE(P30:P32)
C31: 공모사업-꽃의비밀 | D31: 7월 | E31: 2 | F31: 13700000 | G31: 13700000 | H31: =SUM(G31/F31*100) | I31: 1636437 | J31: 50115000 | K31: =SUM(J31/J46*100) | L31: =SUM(J31-G31) | M31: 1892 | N31: 28 | O31: =SUM(M31:N31) | P31: =J31/(G31+I31)*100
C32: 공모사업-쇼팽 | D32: 9월 | E32: 1 | F32: 7362000 | G32: 3003000 | H32: =SUM(G32/F32*100) | I32: 217371 | J32: 7364000 | K32: =SUM(J32/J47*100) | L32: =SUM(J32-G32) | M32: 331 | N32: 57 | O32: =SUM(M32:N32) | P32: =J32/(G32+I32)*100
B34: 구분 | D34: 진행월 | E34: 횟수 | F34: 예산 | G34: 지출 | I34: 판매 수수료 | J34: 매출 | L34: 차액 (a-b) | M34: 인원수 | P34: 수익율 | Q34: 수익율
G35: 전표실적(a) | H35: 비율 | J35: 정산서(b) | K35: 비율 | M35: 판매 | N35: 초대 | O35: 계 | X35: 정산서 | Y35: 브런치패키지 | Z35: 전시패키지 | AA35: 실매출
C36: 브런치콘서트 <오전에 즐기는 클래식> | D36: 3월 | E36: 1 | F36: 8600000 | G36: 8414640 | H36: =SUM(G36/G51*100) | I36: 161700 | J36: =6018000-600000-100000 | K36: =SUM(J36/J51*100) | L36: =SUM(J36-G36) | M36: 309 | N36: 31 | O36: =SUM(M36:N36) | P36: =J36/(G36+I36)*100 | X36: 6018000 | Y36: 600000 | Z36: 100000 | AA36: =X36-Y36-Z36
C37: 브런치콘서트 <냠냠클래식> | D37: 5월 | E37: 1 | F37: 9600000 | G37: 9040000 | I37: 265716 | J37: 6804000 | K37: =SUM(J37/J52*100) | L37: =SUM(J37-G37) | M37: 400 | N37: 34 | O37: =SUM(M37:N37) | P37: =J37/(G37+I37)*100 | X37: 8904000 | Y37: 1640000 | Z37: =115*4000 | AA37: =X37-Y37-Z37
C38: 브런치콘서트 <썸머 페스티벌> | D38: 7월 | E38: 1 | F38: 8600000 | G38: 8157300 | H38: =SUM(G38/G52*100) | I38: 196548 | J38: 6552100 | K38: =SUM(J38/J52*100) | L38: =SUM(J38-G38) | M38: 384 | N38: 23 | O38: =SUM(M38:N38) | P38: =J38/(G38+I38)*100 | X38: 6992100 | Y38: 400000 | Z38: =10*4000 | AA38: =X38-Y38-Z38
C39: 브런치콘서트 <꼬리에 꼬리를 무는 클래식> | D39: 9월 | E39: 1 | F39: 8600000 | G39: 8237800 | I39: 289344 | J39: 8150000 | K39: =SUM(J39/J54*100) | L39: =SUM(J39-G39) | M39: 503 | N39: 33 | O39: =SUM(M39:N39) | P39: =J39/(G39+I39)*100 | X39: 8962000 | Y39: 640000 | Z39: =43*4000 | AA39: =X39-Y39-Z39
C40: 브런치콘서트 <크리스마스가 우리 마을에> | D40: 12월 | E40: 1 | F40: 8600000 | G40: 8556300 | H40: =SUM(G40/G53*100) | I40: 471416 | J40: 14856000 | K40: =SUM(J40/J53*100) | L40: =SUM(J40-G40) | M40: 899 | N40: 10 | O40: =SUM(M40:N40) | P40: =J40/(G40+I40)*100 | X40: 15656000 | Y40: 800000 | AA40: =X40-Y40-Z40
E41: =SUM(E36:E40) | F41: =SUM(F36:F40) | G41: =SUM(G36:G40) | I41: =SUM(I36:I40) | J41: =SUM(J36:J40) | L41: =SUM(L36:L40) | M41: =SUM(M36:M40) | N41: =SUM(N36:N40) | O41: =SUM(O36:O40)

Sheet Claude Log
A1: Turn # | B1: Date | C1: User Request | D1: Action Taken | E1: Details | F1: Outcome
A2: 1 | B2: 46072 | C2: 연간보고실적 시트의 운영실적 데이터가 흩어져 있어 하나로 통합해달라는 요청. 구조 파악 필요. | D2: 데이터 구조 파악 후 통합 계획 제안 | E2: 연간보고실적 시트 분석: A1:E17 연도별 공연실적, A20:E33 문화나눔, G1:K17 2023월별, M1:Q17 2024월별. 새 시트 통합 계획 제시. | F2: 사용자에게 3개 섹션 통합 계획 제안, 승인 대기
A3: 2 | B3: 46072 | C3: 통합 계획 확인 요청에 대해 자유롭게 진행하라고 답변. 새 시트 탭에 파란색 음영 요청. | D3: 통합 시트 생성 완료 | E3: 없음 - 사용자 승인 대기 중이었음 | F3: 사용자 승인 확인, 작업 시작 준비
A4: 3 | B4: 46072 | C4: 운영실적 데이터 통합 실행 + 파란색 탭 시트 생성 | D4: 운영실적통합' 시트 생성, 파란색 탭, 3개 섹션 데이터 통합 | E4: 섹션1: 연도별 공연 종합실적(A3:E18, 2012~2024, SUM 합계). 섹션2: 연도별 문화나눔실적(A20:E35, 공연/전시/소계). 섹션3: 월별 상세(A37:G52, 2023-2024 나란히). 파란색 계열 서식, 줄무늬 배경, 합계 검증 완료. | F4: 합계 검증 완료: 공연횟수 1,929회, 관람인원 886,636명 등 원본과 일치. 운영실적통합 시트 완성.
A5: 4 | B5: 46072 | C5: 세부운영관리대장을 복제하여 서식만 깔끔하게 정리한 Raw 데이터 시트 생성 요청. 데이터 누락 없어야 하며, 누락 열은 추후 검토 예정. | D5: 세부운영관리대장(정리)' 시트 생성 — 원본 복제 후 서식 정리 | E5: 원본 시트(24) 2,236행×28열 그대로 복제. 헤더: 파란색(#2E75B6)+흰글자. 소계 151개 행: 연한 파랑(#D6E4F0)+Bold. 발권합계(R열): 노란 강조(#FFF2CC). 열 너비 최적화, 숫자 #,##0 서식, 시간 h:mm, 자동필터 적용, 틀 고정(행2+열A). V~AA열 '연차보고서 공연실적' 영역 녹색 헤더로 구분. 파란 탭 설정. | F5: 2,236행 완전 복제 확인. 첫행: 2012년 5월 KBS열린음악회, 마지막: 2024년 12월 소계. 합계 검증(R6=7716 일치). 시트 순서: 운영실적통합 → 세부운영관리대장(정리) → 기존시트들.
A6: 5 | B6: 46073 | C6: 일일입력 시트: 기준일자 yyyymmdd 형식 통일, 공연명/공연일 좌측정렬, 숫자/금액 우측정렬 요청 | D6: 기준일자 형식 변환 + 정렬/숫자서식 적용 | E6: B2 수식: =TEXT(TODAY(),"yyyymmdd")로 변경. A16:A55 기준일자 40건 MM/DD→yyyymmdd 변환(2026년 기준). B:C열 좌측정렬, D~O열 우측정렬. 금액열 #,##0, 좌석수열 #,##0, 점유율 0.0% 서식 적용. | F6: 기준일자 yyyymmdd 형식 통일 완료. 정렬/서식 적용 완료. 수식 정상 작동 확인.
A7: 6 | B7: 46073 | C7: 공연 회차별 분리 입력 구조로 변경 요청. 회차/시각 컬럼 추가, 기존 합산 데이터 '회차/2'+빨간색 표기, 판매추이 통합 집계 추가 | D7: 일일입력+판매추이 시트 구조 변경 | E7: [Phase1] 일일입력: D열(회차/시각) 삽입. 상단 입력영역(D5:D9) 및 누적기록(D16:D55)에 시각/회차 정보 입력. 미세스다웃파이어 16건 '회차/2'+연한빨간색(#FDE8E8). 모든 INDEX/MATCH 수식에 회차 조건 추가(B&D 복합검색). 중복체크에 D열 조건 추가. 미리보기(D58:D62) 수식 추가. [Phase2] 판매추이: D열 삽입+수식 추가. R~U열에 공연통합 집계(SUMIFS) 추가. 미세스다웃파이어 행 연한빨간색. | F7: 회차별 분리 구조 완성. 기존 합산 데이터는 '회차/2'+빨간색으로 검토 필요 표시. 판매추이에 통합집계(R~U열) 추가. 향후 다회차 공연 입력 시 통합 집계 자동 작동.
A8: 7 | B8: 46073 | C8: 공연일에서 시각 정보 제거 → 회차/시각 컬럼으로 이동. 2회차 공연(미세스 다웃파이어)은 2행으로 분리 | D8: 공연일 시각 제거 + 미세스다웃파이어 행 분리 | E8: 상단 입력영역: 행7 삽입하여 미세스 14:00/19:00 2행 분리(A6='2-1', A7='2-2'). 모든 공연일 C열에서 시각 제거('2026. 1. 24(토) 14:00 / 19:00'→'2026. 1. 24(토)'). 누적기록 C17:C56 일괄 시각 제거(40건). 미리보기 행61 추가(미세스 19:00용). R열(공연일 날짜 변환) 정상 작동 확인. 판매추이도 자동 반영. | F8: 공연일에서 시각 완전 분리 완료. 회차/시각 컬럼에만 시각 표시. 미세스다웃파이어 14:00/19:00 별도 행으로 분리.
A9: 8 | B9: 46073 | C9: 기존 '회차/2' 데이터 16건을 14:00/19:00 두 행으로 분리 요청 | D9: 미세스다웃파이어 16건 → 32행으로 분리 | E9: 일일입력: 16행 삽입(아래→위 순서로). 각 회차/2 행 → 14:00행 + 19:00행으로 분리. 19:00 행에 A~C, E~P 데이터 복사. Q열(중복체크) 수식도 복사. 모든 32행 연한빨간색 유지(검토 필요). 판매추이: 행42~57에 19:00 행 수식 재작성(일일입력 행 36,38...71 참조). R~U 통합집계 수식도 추가. 통합집계 정상작동 확인(20260125: 14:00+19:00=6,664석, 회차수2). | F9: 16건 회차/2 → 32행 14:00/19:00 분리 완료. 숫자는 기존 합산값 그대로 복사됨(검토 필요 표시). 판매추이 통합집계 정상.
A10: 9 | B10: 46073 | C10: 14:00/19:00 중복 여부 확인 요청 | D10: 데이터 검증 실시 | E10: 56행 전수 검사: 기준일자+공연명+회차/시각 기준 고유키 56건 = 전체 행 56건. Q열 중복체크도 전수 ✅. D열 raw값 확인: 텍스트 '14:00'/'19:00' 교대, 시간 시리얼 없음. | F10: 중복 없음. 56행 모두 고유함 확인 완료.
A11: 10 | B11: 46072 | C11: 2025 파일 4개 시트의 운영실적통합 반영 여부 확인 요청 | D11: 4개 시트(공연장운영관리대장, 세부운영관리대장(2), 기획공연판매현황, 2025공연건수보고) 각각의 반영 상태를 분석하여 보고 | E11: 공연장운영관리대장→Section1,3 반영완료. 세부운영관리대장(2)→세부운영관리대장(정리) 반영완료. 기획공연판매현황→2024기획공연 판매금액 데이터로 미반영(운영실적통합에 해당 섹션 없음). 2025공연건수보고→일정데이터로 미반영(운영실적통합에 해당 섹션 없음). | F11: 4개 중 2개는 반영 완료, 2개는 운영실적통합의 현재 구조에 맞는 섹션이 없어 미반영. 사용자에게 추가 반영 여부 확인 필요.
A12: 11 | B12: 46072 | C12: 운영실적통합에 기획공연 판매실적 섹션 추가 요청 (판매금액 있는 건만) | D12: 기획공연판매현황 시트에서 판매금액이 있는 22건만 추출하여 운영실적통합 Row57~83에 Section 4 추가 | E12: Section 4 '▣ 2024년 기획공연 판매실적' 생성. 헤더(No/공연명/공연횟수/관람인원/판매금액/비고). 22건 데이터 + SUM 합계행. 무료공연(예울마루위크) 판매금액 없어 제외. 합계: 73회, 29,134명, 956,827,919원. 교차색상/테두리/숫자서식 적용. | F12: 운영실적통합 4개 섹션 완성: ①연도별공연(3-19행) ②문화나눔(21-36행) ③월별상세(38-53행) ④기획공연판매(57-83행). 2025파일 4개시트 중 3개 반영완료, 2025공연건수보고는 일정표 성격으로 미반영.
A13: 12 | B13: 46072 | C13: 4번째 시트 외 나머지 전부 통합 완료됐는지 확인 요청 | D13: 전체 15개 시트의 통합 반영 여부를 분석하여 시트별 상태 보고 | E13: 원본 시트 11개 + 2025파일 4개 = 15개. 반영완료: 연간보고실적→Section1,2,3, 공연장운영관리대장(원본+2025)→Section1,3 2025업데이트, 세부운영관리대장→세부(정리), 기획공연판매현황→Section4. 미반영: 기준(감면기준표), 공연장운영관리대장요약(연도별요약), 관람객기준(유료객석점유율), 기획공연데이터~2021(상세정산), 공연장운영관리대장(기존)(과거버전), 2025공연건수보고(일정표). | F13: 핵심 실적 데이터는 모두 통합 완료. 나머지 미반영 시트들은 '기준/참조 테이블'이거나 '과거 버전', '정산 상세' 등 성격이 다른 보조 데이터.
... A27: 25 | B27: 46073 | C27: 소스 시트 3개(기획공연판매현황, 세부운영관리대장, 공연장운영관리대장) 삭제 요청 | D27: 참조 수식 확인 후 3개 소스 시트 삭제 | E27: 삭제 전 25공연, 운영실적통합, 세부운영관리대장(정리), Claude Log 시트에서 소스 시트 참조 수식 검사 → 0건 확인. 기획공연판매현황, 세부운영관리대장, 공연장운영관리대장 3개 시트 삭제 완료. | F27: 남은 시트: 25공연(0), Claude Log(1), 운영실적통합(2), 세부운영관리대장(정리)(3). 총 4개 시트.
A28: Turn 10 | B28: 46073 | C28: 일일 판매현황 시트를 운영실적통합에 연동하는 아키텍처 설계 및 구현 요청. 판매추이 통합 시트 생성 + 기존 28개 일일 시트 데이터 자동 이관 + 운영실적통합 연동. | D28: 1) 26개 일일 시트(0103~0219) 구조 분석, 2) '판매추이' 시트 신규 생성, 3) 5개 공연 × 40건 데이터 추출·이관, 4) 운영실적통합 Row 173~182에 '2026년 기획공연 판매현황(실시간)' 섹션 추가, LOOKUP 수식으로 판매추이 최신 데이터 자동 참조 | E28: Option B 아키텍처 선택: 판매추이 통합 시트(DB형). 공연명: 신년음악회/미세스다웃파이어/100층짜리집/실내악페스티벌/브런치콘서트. LOOKUP(2,1/(조건),결과) 패턴 사용 - 마지막 일치 행의 값을 반환. 날짜 형식 MM/DD 텍스트. 기존 28개 일일 시트는 아직 미삭제 (사용자 확인 필요). | F28: 판매추이 시트 완성(40행), 운영실적통합 173~182행 실시간 참조 섹션 완성. 5개 공연 합계: 5,508석 / 567,968,450원. 향후: 새 데이터 추가 시 판매추이에 행 추가만 하면 운영실적통합 자동 반영. 기존 일일 시트 삭제 여부 사용자에게 확인 필요.
A29: 27 | B29: 46073 | C29: 일일입력 시트 생성 요청. 판매현황(사전판매 추이) + 공연실적(최종 실적) 두 가지를 모두 입력할 수 있는 양식이 필요. 매일 한 번 입력, 중복 날짜 방지 필요. | D29: 일일입력 시트 생성 + 판매추이 중복 조건부서식 추가 | E29: 3개 영역 구성: (1) 판매현황 입력(행7-13): 5개 공연별 유료좌석/금액/예약/무료 입력, 합계/점유율/전일대비 자동계산, COUNTIFS 중복체크. (2) 공연실적 입력(행17-24): 세부운영관리대장 C:AA열과 1:1 매핑(25개 열), 발권합계/수표합계/공연인원합 자동계산. (3) 판매추이 복사 미리보기(행35-42): 입력 데이터를 판매추이 형식으로 자동 변환. 기준일자=TODAY() 자동입력, 파란글씨=입력셀, 노란배경=수정가능. 판매추이에 COUNTIFS 중복 조건부서식(빨간배경) 추가. | F29: 일일입력 시트 완성. 실무자가 판매현황 입력 → 미리보기 영역 복사 → 판매추이에 값 붙여넣기 워크플로우. 공연실적은 별도 영역에서 입력 → 세부운영관리대장에 복사. 운영실적통합은 기존 LOOKUP 수식으로 판매추이 자동 참조 유지.
A30: 29 | B30: 46073 | C30: 일일입력을 누적 기록 시트로 재설계 요청. 기록이 날짜별로 쌓이고, 과거 조회 가능해야 함 (예: 2/18 기준 판매량). 판매추이는 최신본 자동 연동. | D30: 일일입력 시트 전면 재설계 + 판매추이 수식 미러 시트로 변환 | E30: 일일입력: 임시 양식 → 누적 기록 시트로 변환. 행4=헤더(A~O 15열+P 중복체크), 행5~44=기존 40행 데이터 마이그레이션(01/03~02/19), 필터+틀고정 적용. 판매추이: 정적 데이터 → =IF(OR(일일입력!A{r}="",일일입력!E{r}=""),"",일일입력!{col}{r}) 수식으로 500행 자동 참조. E열(유료좌석) 비어있으면 행 미표시 → 빈 placeholder가 운영실적통합 LOOKUP에 영향 안 줌. A열 텍스트형식(@) 적용으로 MM/DD 형식 유지. 중복체크(P열): COUNTIFS로 동일 날짜+공연 감지, 조건부서식으로 빨간 강조. | F30: 데이터 흐름 완성: 일일입력(누적기록) → 판매추이(수식미러) → 운영실적통합(LOOKUP 대시보드). 5개 공연 모두 정상 표시. 과거 데이터 필터로 조회 가능. 2/20 데이터는 실무자가 직접 행 추가하여 입력 필요.
A31: 30 | B31: 46073 | C31: 입력창과 누적창 분리 요청. 오늘 날짜 기준 입력창(전일 데이터 참조) + 아래에 자동 누적 로그. 데이터 흐름: 입력창 → 누적창 → 판매추이 → 세부운영 → 운영실적통합 | D31: 일일입력 시트 전면 재설계: 입력창(행1-10) + 누적창(행12-55) + 미리보기(행56-62) 3영역 분리 | E31: 입력창: B2=TODAY() 자동날짜, 5개 공연×(유료좌석~무료좌석) 노란색 입력셀, J-K=합계수식, L=점유율 자동계산(총좌석역산), M=중복체크(COUNTIFS), N=전일유료좌석(LOOKUP). 누적창: 행15=필터헤더+틀고정, 행16~55=기존40행 마이그레이션, P열=중복체크+조건부서식. 미리보기: 행58~62=입력창→누적형식 자동변환(복사→값붙여넣기 워크플로우). 판매추이: 500행 수식을 일일입력!행16+ 참조로 업데이트. E열 비어있으면 미표시(LOOKUP 안전). | F31: 3영역 분리 완성. 입력창(오늘 날짜+전일참고), 누적창(40행 기록+필터), 미리보기(복사용). 판매추이→운영실적통합 전체 데이터 체인 정상 검증. 과거 날짜 조회=필터 사용.
A32: 31 | B32: 46073 | C32: 누적창을 최신 날짜가 위에 오도록 정렬하고, 입력창에 가장 최근 자료가 자동으로 올라오게 해달라는 요청 | D32: 누적창 역순 정렬 + 입력창 전일 데이터 자동 채움 + 운영실적통합 수식 변환 | E32: 누적창: 40행 데이터를 역순 정렬(02/19→01/03). 입력창 E~I열: INDEX/MATCH 수식으로 누적창의 첫 번째 일치(=최신) 데이터를 자동 불러옴. 사용자가 값만 수정하면 됨. 운영실적통합: LOOKUP(마지막일치) → INDEX/MATCH(첫일치)로 전환하여 역순 호환. 미리보기 M,N열(전일대비)도 INDEX/MATCH로 수정. A열 텍스트/General 형식 문제 해결. | F32: 입력창에 전일 데이터 자동 표시(918, 3332, 807, 287, 164). 누적창 최신순 정렬. 전체 데이터 체인 정상: 일일입력→판매추이→운영실적통합(합계 5,508석/567,968,450원). 새 데이터는 누적 맨 위에 행 삽입+값 붙여넣기로 추가.
A33: 32 | B33: 46073 | C33: 입력창에서 전일 자동값은 회색, 사용자가 수정한 값은 파란색으로 구분해달라는 요청 | D33: E5:I9에 ISFORMULA 기반 조건부서식 2개 적용 | E33: 조건부서식: (1) =ISFORMULA(E5) → 회색(#999999), 보통체 = 전일 자동 불러온 값. (2) =NOT(ISFORMULA(E5)) → 파란색(#0000FF), 굵게 = 사용자가 직접 수정한 값. 원리: 수식이 있으면 자동값, 사용자가 숫자를 입력하면 수식이 값으로 대체되어 파란색으로 변경. 행10 안내 문구에 색상 범례 추가. | F33: 입력창 E~I열에 색상 구분 적용 완료. 현재 모든 셀이 수식(회색)으로 표시됨. 사용자가 값을 입력하면 즉시 파란색+굵게로 전환됨.
A34: 33 | B34: 46073 | C34: 만료 공연 입력창 숨김 처리 완료 및 Q열 그룹화. 공연일 < TODAY() 인 공연은 입력창에서 '공연종료'로 표시하고, 만료 행에 회색+취소선 조건부서식 적용. Q열(날짜파싱 헬퍼) 그룹화 후 숨김 처리. | D34: Q열 그룹+숨김, 만료 행 조건부서식(회색배경+취소선) 추가, 전체 시스템 검증 | E34: Q열: group(byColumns)+columnHidden=true 적용. 조건부서식: $Q5<TODAY() → 글자색 #BBBBBB, 취소선, 배경 #F0F0F0. 입력창 행5(신년음악회 01/09)·행6(미세스다웃파이어 01/24): E열 '공연종료' 표시, F-N열 공란. 행7-9(100층짜리집, 실내악페스, 브런치콘서트): 정상 표시. 미리보기(행58-62): 만료 공연 자동 공란. 판매추이: 일일입력 행16+ 수식 참조 정상 동작 확인. | F34: 공연종료 필터링 완료. 입력창: 만료 2건(회색+취소선) / 활성 3건(데이터 자동 로드). 누적로그(행16-55): 40건 전체 보존. 판매추이→운영실적통합 데이터 체인 정상.
A35: Turn 10-new | B35: 46073 | C35: 종료된 공연은 빗금이 아니라 아예 입력창에서 안 보이게 해달라는 요청 | D35: 종료 공연 행 삭제, 미리보기 정리 | E35: 입력영역 행5~7(신년음악회, 미세스14:00, 미세스19:00) 삭제 → 진행중 3개만 표시(어린이뮤지컬/실내악/브런치). A열 번호 1~3으로 재정렬. 미리보기 행72~74도 #REF! 발생한 3행 삭제, 남은 3행만 유지. 안내 텍스트의 행번호 참조 모두 수정(행5~7, 행72~74, 행14). | F35: 입력창에 진행중 공연 3건만 깨끗하게 표시. 미리보기도 3행으로 축소. 수식/참조 모두 정상 동작 확인.
A36: Turn 35 | B36: 46073 | C36: 일일입력(2)의 누적 기록 데이터를 일일입력 시트로 옮기고, 2024~2026년 2월까지 날짜 데이터가 잘 들어와 있는지 확인 요청 | D36: 두 시트 구조/데이터 비교 분석 | E36: 일일입력(2): 487행, 148개 고유날짜(20241221~20260219). 일일입력: 56행, 26개 고유날짜(20260103~20260219). 2024년 3일분+2025년 119일분 데이터가 일일입력에 누락. 2026년 26일분은 양쪽 동일. | F36: 일일입력(2)→일일입력 시트로 2024~2025년 데이터 복사 필요. 사용자 확인 대기 중.
A37: Turn 36 | B37: 46073 | C37: 일일입력(3) 시트가 추가됨. 2024년말~2025년 데이터가 모두 있는지 확인 요청 | D37: 일일입력(2)와 일일입력(3) 전체 데이터 비교 | E37: 487행×17열 = 8,279셀 전수 비교. 불일치 0건으로 완전 동일. 148개 고유 날짜(20241221~20260219): 2024년 3일, 2025년 119일, 2026년 26일. 일일입력 시트에는 2026년 26일(56행)만 존재하여 2024~2025년분 431행 누락. | F37: 일일입력(3) = 일일입력(2) 완전 동일 확인. 일일입력 시트로 2024~2025 데이터 복사 필요. 사용자 확인 대기.
A38: Turn 37 | B38: 46073 | C38: 일일입력(3) 자체에 데이터가 다 있는지 확인 요청 (옮기는 게 아님) | D38: 이전 분석 결과 재정리하여 답변 | E38: 일일입력(3) = 487행, 148개 고유 날짜. 2024년 3일 + 2025년 119일 + 2026년 26일. 원본(일일입력(2))과 8,279셀 전수비교 불일치 0건. | F38: 일일입력(3)에 2024년말~2026년 2월 데이터 전부 정상 확인 완료.
A39: Turn 38 | B39: 46073 | C39: 일일입력(3)의 2024~2025년 데이터를 일일입력 시트로 옮겨서 비어있는 기간 채우기 | D39: 일일입력 시트 행70에 431행 삽입 후 일일입력(3)의 2024~2025 데이터 복사 | E39: 일일입력(3) A70:Q500(431행)을 일일입력 A70:Q500으로 복사. 기존 2026년 56행(14~69) 뒤에 2024~2025년 431행 추가. 전수검증: 8,279셀 불일치 0건. 총 487행, 148개 고유날짜(20241221~20260219). 미리보기 영역은 행501 이하로 자동 이동됨. | F39: 일일입력 시트에 2024.12~2026.02 전체 기간 데이터 완성. 일일입력(3)과 완전 동일 확인.
A40: Turn 39 | B40: 46073 | C40: 일일입력 시트 날짜 누락 최종 검증 + 일일입력(2), 일일입력(3) 시트 삭제 | D40: 전체 날짜 검증 후 두 시트 삭제 | E40: 일일입력: 490행, 149개 고유날짜. 월별: 2024/12(3) 2025/01(18) 02(15) 03(20) 04(22) 05(19) 06(18) 07(7) 2026/01(18) 02(9). 유일한 갭 2025.07.08→2026.01.03(179일)은 원본 데이터에도 없는 기간(하반기 미등록). 일일입력(2), 일일입력(3) 삭제 완료. | F40: 일일입력 시트에 전체 기간 데이터 완성 확인. 불필요 시트 정리 완료.
A41: Turn 40 | B41: 46073 | C41: 일일입력 시트의 누적 기록(14행~)이 일자순으로 정렬되어 있지 않아 최신→과거 순 내림차순 정렬 요청 | D41: 487개 누적 기록 행을 기준일자(A열) 내림차순으로 정렬 | E41: A14:Q500 범위 487행을 JS로 읽어 기준일자 내림차순 정렬 후 덮어쓰기. 날짜 범위: 20260219(최신)~20241221(최구). 미리보기 섹션(501행~) 및 R열(수식)은 변경하지 않음. | F41: 정렬 완료. 최신일자 20260219부터 최구 20241221까지 내림차순 나열 확인.
A42: Turn 41 | B42: 46073 | C42: 2025년 7월 이후 내역이 있는지 확인 요청 | D42: 정렬된 누적 기록에서 날짜 분포 확인 | E42: 검색 결과: 20250708(7/8)이 마지막, 이후 20260103(1/3)까지 약 6개월 공백 확인. 7월 1~8일 데이터는 존재함. | F42: 20250708 이후 ~ 20260103 이전 약 6개월간 입력 내역 없음 확인. 사용자에게 안내 완료.
A43: Turn 42 | B43: 46073 | C43: 일일입력 (2) 시트에 2025년 7월 8일 이후 데이터가 있는지 확인 요청 | D43: 일일입력 (2) 시트의 A열을 월별 검색하여 날짜 분포 확인 | E43: 7월(151건 7/9~7/31), 8월(135건), 9월(125건), 10월(132건), 11월(117건), 12월(73건) = 총 733건 확인. 행 범위: A503~A1196. 원본 일일입력에 없던 20250709~20251230 데이터가 모두 존재. | F43: 일일입력 (2)에 빠진 6개월분 데이터 733건 확인 완료. 사용자에게 원본 시트 병합 제안.
A44: Turn 43 | B44: 46073 | C44: 일일입력 (2)의 누락 데이터를 원본 일일입력에 병합 승인 | D44: 일일입력 (2)에서 694건(20250709~20251230) 추출 → 원본 487건과 합쳐 1,181건으로 병합 후 날짜 내림차순 정렬 | E44: 694행 삽입 후 3회 청크(500+500+181행)로 기록. A14:Q1194 범위. 전환구간(7/8→7/9) 정상 확인. 최신 20260219, 최구 20241221. | F44: 병합 완료. 원본 일일입력에 2024.12~2026.02 연속 데이터 1,181건 확보. 빈틀 없이 연결됨.
A45: Turn 44 | B45: 46073 | C45: 일일입력 (2) 시트 삭제 요청 + 기존 일일입력에 반영 완료 확인 | D45: 일일입력 (2) 시트 삭제 | E45: 병합 완료 확인 후 일일입력 (2) 시트 삭제 실행. 원본 일일입력에 1,181건 전체 데이터 보유 확인. | F45: 일일입력 (2) 삭제 완료. 원본 일일입력 시트에만 데이터 통합 관리.
A46: Turn 45 | B46: 46073 | C46: 일일입력 전체 데이터의 C열(공연일)에서 시각 정보를 제거하고, 2026년 데이터처럼 공연일/회차시각 분리 요청 | D46: C열(공연일) 1,125건에서 시각 제거. D열(회차/시각)은 이미 분리 완료 상태 확인. | E46: C열의 '2025. 09. 18(목) 10:30 / 14:30' → '2025. 09. 18(목)' 형태로 변환. 멀티라인 공연일은 각 줄에서 시각만 제거하고 날짜 유지. 1,181행 모두 고유키(일자+공연명+시각) 중복 없음 확인. 회차별 행 분리는 이미 되어있어 추가 작업 불필요. | F46: C열 정리 완료. 1,125건 수정, 56건(2026년)은 이미 정상. 전체 1,181행 공연일-회차/시각 분리 완성.
... A71: Turn 3 | B71: 46114 | C71: SharePoint Graph API로 원격 엑셀 파일의 테스트 데이터 삭제 요청 | D71: 수행 불가 안내. 외부 API/인증/원격파일 접근은 Excel 애드인 범위 밖임을 설명. | E71: Graph API 호출, Azure 인증, secrets.toml 파일 읽기, 원격 SharePoint 파일 수정 모두 불가. 현재 워크북 내 동일 조건 삭제는 가능함을 안내. | F71: 대안으로 현재 워크북에서 해당 행 삭제 가능 여부 확인 중. Power Automate/Python Graph SDK 권장.

Sheet 일일입력
A1: 📝 당일 판매현황 입력
A2: 기준일자 | B2: =TEXT(TODAY(),"yyyymmdd") | C2: ← 오늘 날짜 자동 (수정 가능: yyyymmdd 형식)
A4: No | B4: 공연명 | C4: 공연일 | D4: 회차/시각 | E4: 오픈석 | F4: 유료좌석 | G4: 유료금액 | H4: 예약좌석 | I4: 예약금액 | J4: 무료좌석 | K4: 합계좌석 | L4: 합계금액 | M4: 점유율 | N4: 중복체크 | O4: 전일(참고) | R4: 공연일(날짜)
A5: 1 | B5: 2026 어린이 뮤지컬 <100층짜리 집> | C5: 2026. 5. 14(목) | D5: 11:00 | E5: 5562 | F5: {=IF(R5<TODAY(),"공연종료",IFERROR(INDEX($F$17:$F$7593,MATCH(B5&D5,$B$17:$B$7593&$D$17:$D$7593,0)),""))} | G5: {=IF(R5<TODAY(),"",IFERROR(INDEX($G$17:$G$7593,MATCH(B5&D5,$B$17:$B$7593&$D$17:$D$7593,0)),""))} | H5: {=IF(R5<TODAY(),"",IFERROR(INDEX($H$17:$H$7593,MATCH(B5&D5,$B$17:$B$7593&$D$17:$D$7593,0)),""))} | I5: {=IF(R5<TODAY(),"",IFERROR(INDEX($I$17:$I$7593,MATCH(B5&D5,$B$17:$B$7593&$D$17:$D$7593,0)),""))} | J5: {=IF(R5<TODAY(),"",IFERROR(INDEX($J$17:$J$7593,MATCH(B5&D5,$B$17:$B$7593&$D$17:$D$7593,0)),""))} | K5: =IF(R5<TODAY(),"",F5+H5+J5) | L5: =IF(R5<TODAY(),"",G5+I5) | M5: {=IF(R5<TODAY(),"",IFERROR(K5/(INDEX($K$17:$K$7593,MATCH(B5&D5,$B$17:$B$7593&$D$17:$D$7593,0))/INDEX($M$17:$M$7593,MATCH(B5&D5,$B$17:$B$7593&$D$17:$D$7593,0))),""))} | N5: =IF(R5<TODAY(),"",IF(F5="","",IF(COUNTIFS($A$17:$A$7593,$B$2,$B$17:$B$7593,B5,$D$17:$D$7593,D5)>0,"⚠ 중복!","✅ 신규"))) | O5: {=IF(R5<TODAY(),"",IFERROR(INDEX($F$17:$F$7593,MATCH(B5&D5,$B$17:$B$7593&$D$17:$D$7593,0)),"(신규)"))} | R5: =IFERROR(DATE(LEFT(C5,4),TRIM(MID(C5,6,FIND(".",C5,6)-6)),TRIM(MID(C5,FIND(".",C5,6)+1,FIND("(",C5)-FIND(".",C5,6)-1))),"")
A6: 2 | B6: 2026 GS칼텍스 예울마루 실내악 페스티벌 | C6: 2026. 4. 16(목) | D6: 19:30 | E6: 3704 | F6: {=IF(R6<TODAY(),"공연종료",IFERROR(INDEX($F$17:$F$7593,MATCH(B6&D6,$B$17:$B$7593&$D$17:$D$7593,0)),""))} | G6: {=IF(R6<TODAY(),"",IFERROR(INDEX($G$17:$G$7593,MATCH(B6&D6,$B$17:$B$7593&$D$17:$D$7593,0)),""))} | H6: {=IF(R6<TODAY(),"",IFERROR(INDEX($H$17:$H$7593,MATCH(B6&D6,$B$17:$B$7593&$D$17:$D$7593,0)),""))} | I6: {=IF(R6<TODAY(),"",IFERROR(INDEX($I$17:$I$7593,MATCH(B6&D6,$B$17:$B$7593&$D$17:$D$7593,0)),""))} | J6: {=IF(R6<TODAY(),"",IFERROR(INDEX($J$17:$J$7593,MATCH(B6&D6,$B$17:$B$7593&$D$17:$D$7593,0)),""))} | K6: =IF(R6<TODAY(),"",F6+H6+J6) | L6: =IF(R6<TODAY(),"",G6+I6) | M6: {=IF(R6<TODAY(),"",IFERROR(K6/(INDEX($K$17:$K$7593,MATCH(B6&D6,$B$17:$B$7593&$D$17:$D$7593,0))/INDEX($M$17:$M$7593,MATCH(B6&D6,$B$17:$B$7593&$D$17:$D$7593,0))),""))} | N6: =IF(R6<TODAY(),"",IF(F6="","",IF(COUNTIFS($A$17:$A$7593,$B$2,$B$17:$B$7593,B6,$D$17:$D$7593,D6)>0,"⚠ 중복!","✅ 신규"))) | O6: {=IF(R6<TODAY(),"",IFERROR(INDEX($F$17:$F$7593,MATCH(B6&D6,$B$17:$B$7593&$D$17:$D$7593,0)),"(신규)"))} | R6: =IFERROR(DATE(LEFT(C6,4),TRIM(MID(C6,6,FIND(".",C6,6)-6)),TRIM(MID(C6,FIND(".",C6,6)+1,FIND("(",C6)-FIND(".",C6,6)-1))),"")
A7: 3 | B7: 2026 GS칼텍스 예울마루 브런치콘서트 | C7: 2026. 4. 9(목) | D7: 11:00 | E7: 926 | F7: {=IF(R7<TODAY(),"공연종료",IFERROR(INDEX($F$17:$F$7593,MATCH(B7&D7,$B$17:$B$7593&$D$17:$D$7593,0)),""))} | G7: {=IF(R7<TODAY(),"",IFERROR(INDEX($G$17:$G$7593,MATCH(B7&D7,$B$17:$B$7593&$D$17:$D$7593,0)),""))} | H7: {=IF(R7<TODAY(),"",IFERROR(INDEX($H$17:$H$7593,MATCH(B7&D7,$B$17:$B$7593&$D$17:$D$7593,0)),""))} | I7: {=IF(R7<TODAY(),"",IFERROR(INDEX($I$17:$I$7593,MATCH(B7&D7,$B$17:$B$7593&$D$17:$D$7593,0)),""))} | J7: {=IF(R7<TODAY(),"",IFERROR(INDEX($J$17:$J$7593,MATCH(B7&D7,$B$17:$B$7593&$D$17:$D$7593,0)),""))} | K7: =IF(R7<TODAY(),"",F7+H7+J7) | L7: =IF(R7<TODAY(),"",G7+I7) | M7: {=IF(R7<TODAY(),"",IFERROR(K7/(INDEX($K$17:$K$7593,MATCH(B7&D7,$B$17:$B$7593&$D$17:$D$7593,0))/INDEX($M$17:$M$7593,MATCH(B7&D7,$B$17:$B$7593&$D$17:$D$7593,0))),""))} | N7: =IF(R7<TODAY(),"",IF(F7="","",IF(COUNTIFS($A$17:$A$7593,$B$2,$B$17:$B$7593,B7,$D$17:$D$7593,D7)>0,"⚠ 중복!","✅ 신규"))) | O7: {=IF(R7<TODAY(),"",IFERROR(INDEX($F$17:$F$7593,MATCH(B7&D7,$B$17:$B$7593&$D$17:$D$7593,0)),"(신규)"))} | R7: =IFERROR(DATE(LEFT(C7,4),TRIM(MID(C7,6,FIND(".",C7,6)-6)),TRIM(MID(C7,FIND(".",C7,6)+1,FIND("(",C7)-FIND(".",C7,6)-1))),"")
A8: 4 | B8: 한국페스티발앙상블 <세상에서 가장 편한 음악> | C8: 2026. 5. 23(토) | D8: 17:00 | E8: 926 | F8: {=IF(R8<TODAY(),"공연종료",IFERROR(INDEX($F$17:$F$7593,MATCH(B8&D8,$B$17:$B$7593&$D$17:$D$7593,0)),""))} | G8: {=IF(R8<TODAY(),"",IFERROR(INDEX($G$17:$G$7593,MATCH(B8&D8,$B$17:$B$7593&$D$17:$D$7593,0)),""))} | H8: {=IF(R8<TODAY(),"",IFERROR(INDEX($H$17:$H$7593,MATCH(B8&D8,$B$17:$B$7593&$D$17:$D$7593,0)),""))} | I8: {=IF(R8<TODAY(),"",IFERROR(INDEX($I$17:$I$7593,MATCH(B8&D8,$B$17:$B$7593&$D$17:$D$7593,0)),""))} | J8: {=IF(R8<TODAY(),"",IFERROR(INDEX($J$17:$J$7593,MATCH(B8&D8,$B$17:$B$7593&$D$17:$D$7593,0)),""))} | K8: =IF(R8<TODAY(),"",F8+H8+J8) | L8: =IF(R8<TODAY(),"",G8+I8) | M8: {=IF(R8<TODAY(),"",IFERROR(K8/(INDEX($K$17:$K$7593,MATCH(B8&D8,$B$17:$B$7593&$D$17:$D$7593,0))/INDEX($M$17:$M$7593,MATCH(B8&D8,$B$17:$B$7593&$D$17:$D$7593,0))),""))} | N8: =IF(R8<TODAY(),"",IF(F8="","",IF(COUNTIFS($A$17:$A$7593,$B$2,$B$17:$B$7593,B8,$D$17:$D$7593,D8)>0,"⚠ 중복!","✅ 신규"))) | O8: {=IF(R8<TODAY(),"",IFERROR(INDEX($F$17:$F$7593,MATCH(B8&D8,$B$17:$B$7593&$D$17:$D$7593,0)),"(신규)"))} | R8: =IFERROR(DATE(LEFT(C8,4),TRIM(MID(C8,6,FIND(".",C8,6)-6)),TRIM(MID(C8,FIND(".",C8,6)+1,FIND("(",C8)-FIND(".",C8,6)-1))),"")
A9: 5 | B9: 국립심포니오케스트라 | C9: 2026. 5. 30(토) | D9: 15:00 | E9: 926 | F9: {=IF(R9<TODAY(),"공연종료",IFERROR(INDEX($F$17:$F$7593,MATCH(B9&D9,$B$17:$B$7593&$D$17:$D$7593,0)),""))} | G9: {=IF(R9<TODAY(),"",IFERROR(INDEX($G$17:$G$7593,MATCH(B9&D9,$B$17:$B$7593&$D$17:$D$7593,0)),""))} | H9: {=IF(R9<TODAY(),"",IFERROR(INDEX($H$17:$H$7593,MATCH(B9&D9,$B$17:$B$7593&$D$17:$D$7593,0)),""))} | I9: {=IF(R9<TODAY(),"",IFERROR(INDEX($I$17:$I$7593,MATCH(B9&D9,$B$17:$B$7593&$D$17:$D$7593,0)),""))} | J9: {=IF(R9<TODAY(),"",IFERROR(INDEX($J$17:$J$7593,MATCH(B9&D9,$B$17:$B$7593&$D$17:$D$7593,0)),""))} | K9: =IF(R9<TODAY(),"",F9+H9+J9) | L9: =IF(R9<TODAY(),"",G9+I9) | M9: {=IF(R9<TODAY(),"",IFERROR(K9/(INDEX($K$17:$K$7593,MATCH(B9&D9,$B$17:$B$7593&$D$17:$D$7593,0))/INDEX($M$17:$M$7593,MATCH(B9&D9,$B$17:$B$7593&$D$17:$D$7593,0))),""))} | N9: =IF(R9<TODAY(),"",IF(F9="","",IF(COUNTIFS($A$17:$A$7593,$B$2,$B$17:$B$7593,B9,$D$17:$D$7593,D9)>0,"⚠ 중복!","✅ 신규"))) | O9: {=IF(R9<TODAY(),"",IFERROR(INDEX($F$17:$F$7593,MATCH(B9&D9,$B$17:$B$7593&$D$17:$D$7593,0)),"(신규)"))} | R9: =IFERROR(DATE(LEFT(C9,4),TRIM(MID(C9,6,FIND(".",C9,6)-6)),TRIM(MID(C9,FIND(".",C9,6)+1,FIND("(",C9)-FIND(".",C9,6)-1))),"")
A10: 6 | B10: 김영욱x콜레기움 무지쿰 서울 <8 Seasons> | C10: 2026. 5. 7(목) | D10: 19:30 | E10: 926 | F10: {=IF(R10<TODAY(),"공연종료",IFERROR(INDEX($F$17:$F$7593,MATCH(B10&D10,$B$17:$B$7593&$D$17:$D$7593,0)),""))} | G10: {=IF(R10<TODAY(),"",IFERROR(INDEX($G$17:$G$7593,MATCH(B10&D10,$B$17:$B$7593&$D$17:$D$7593,0)),""))} | H10: {=IF(R10<TODAY(),"",IFERROR(INDEX($H$17:$H$7593,MATCH(B10&D10,$B$17:$B$7593&$D$17:$D$7593,0)),""))} | I10: {=IF(R10<TODAY(),"",IFERROR(INDEX($I$17:$I$7593,MATCH(B10&D10,$B$17:$B$7593&$D$17:$D$7593,0)),""))} | J10: {=IF(R10<TODAY(),"",IFERROR(INDEX($J$17:$J$7593,MATCH(B10&D10,$B$17:$B$7593&$D$17:$D$7593,0)),""))} | K10: =IF(R10<TODAY(),"",F10+H10+J10) | L10: =IF(R10<TODAY(),"",G10+I10) | M10: {=IF(R10<TODAY(),"",IFERROR(K10/(INDEX($K$17:$K$7593,MATCH(B10&D10,$B$17:$B$7593&$D$17:$D$7593,0))/INDEX($M$17:$M$7593,MATCH(B10&D10,$B$17:$B$7593&$D$17:$D$7593,0))),""))} | N10: =IF(R10<TODAY(),"",IF(F10="","",IF(COUNTIFS($A$17:$A$7593,$B$2,$B$17:$B$7593,B10,$D$17:$D$7593,D10)>0,"⚠ 중복!","✅ 신규"))) | O10: {=IF(R10<TODAY(),"",IFERROR(INDEX($F$17:$F$7593,MATCH(B10&D10,$B$17:$B$7593&$D$17:$D$7593,0)),"(신규)"))} | R10: =IFERROR(DATE(LEFT(C10,4),TRIM(MID(C10,6,FIND(".",C10,6)-6)),TRIM(MID(C10,FIND(".",C10,6)+1,FIND("(",C10)-FIND(".",C10,6)-1))),"")
A11: 💡 회색 = 전일 자동 불러온 값 (수정 불필요 시 그대로) | 파란색 = 내가 수정한 값 | 노란 셀(E~I열)에 직접 숫자를 입력하면 파란색으로 바뀝니다
A13: 📚 누적 기록 (자동 로그)
A14: ※ 입력창에서 데이터 입력 시 이 영역에 자동으로 누적됩니다. 이 영역의 데이터는 직접 수정하지 마세요. 필터로 과거 날짜 조회가 가능합니다.
A16: 기준일자 | B16: 공연명 | C16: 공연일 | D16: 회차/시각 | E16: 오픈석 | F16: 유료좌석 | G16: 유료금액 | H16: 예약좌석 | I16: 예약금액 | J16: 무료좌석 | K16: 합계좌석 | L16: 합계금액 | M16: 점유율 | N16: 전일대비(석) | O16: 전일대비(원) | P16: 객단가 | Q16: 중복체크
A17: 20260401 | B17: 김영욱x콜레기움 무지쿰 서울 <8 Seasons> | C17: 2026. 5. 7(목) | D17: 19:30 | E17: 926 | F17: 89 | G17: 1633500 | H17: 0 | I17: 0 | J17: 0 | K17: 89 | L17: 1633500 | M17: 0.096112311 | N17: 0 | O17: 0 | P17: 18354 | Q17: ✅
A18: 20260401 | B18: 국립심포니오케스트라 | C18: 2026. 5. 30(토) | D18: 15:00 | E18: 926 | F18: 141 | G18: 5954000 | H18: 0 | I18: 0 | J18: 0 | K18: 141 | L18: 5954000 | M18: 0.15226782 | N18: 0 | O18: 0 | P18: 42227 | Q18: ✅
A19: 20260401 | B19: 한국페스티발앙상블 <세상에서 가장 편한 음악> | C19: 2026. 5. 23(토) | D19: 17:00 | E19: 926 | F19: 92 | G19: 2742000 | H19: 0 | I19: 0 | J19: 0 | K19: 92 | L19: 2742000 | M19: 0.099352052 | N19: 2 | O19: 70000 | P19: 29804 | Q19: ✅
A20: 20260401 | B20: 2026 GS칼텍스 예울마루 브런치콘서트 | C20: 2026. 4. 9(목) | D20: 11:00 | E20: 926 | F20: 263 | G20: 5178000 | H20: 0 | I20: 0 | J20: 0 | K20: 263 | L20: 5178000 | M20: 0.28401728 | N20: 0 | O20: 4000 | P20: 19688 | Q20: ✅
A21: 20260401 | B21: 2026 GS칼텍스 예울마루 실내악 페스티벌 | C21: 2026. 4. 16(목) | D21: 19:30 | E21: 294 | F21: 475 | G21: 13293000 | H21: 0 | I21: 0 | J21: 0 | K21: 475 | L21: 13293000 | M21: 0.12823974 | N21: 9 | O21: 392000 | P21: 27985 | Q21: ✅
A22: 20260401 | B22: 2026 어린이 뮤지컬 <100층짜리 집> | C22: 2026. 5. 14(목) | D22: 11:00 | E22: 294 | F22: 1291 | G22: 49485100 | H22: 0 | I22: 0 | J22: 0 | K22: 1291 | L22: 49485100 | M22: 0.23211075 | N22: 157 | O22: 4914700 | P22: 38331 | Q22: ✅
A23: 20260401 | B23: 김영욱x콜레기움 무지쿰 서울 <8 Seasons> | C23: 2026. 5. 7(목) | D23: 19:30 | E23: 926 | F23: 89 | G23: 1633500 | H23: 0 | I23: 0 | J23: 0 | K23: 89 | L23: 1633500 | M23: 0.096112311 | N23: 0 | O23: 0 | P23: 18354 | Q23: ✅
A24: 20260401 | B24: 국립심포니오케스트라 | C24: 2026. 5. 30(토) | D24: 15:00 | E24: 926 | F24: 141 | G24: 5954000 | H24: 0 | I24: 0 | J24: 0 | K24: 141 | L24: 5954000 | M24: 0.15226782 | N24: 0 | O24: 0 | P24: 42227 | Q24: ✅
A25: 20260401 | B25: 한국페스티발앙상블 <세상에서 가장 편한 음악> | C25: 2026. 5. 23(토) | D25: 17:00 | E25: 926 | F25: 90 | G25: 2672000 | H25: 0 | I25: 0 | J25: 0 | K25: 90 | L25: 2672000 | M25: 0.097192225 | N25: 0 | O25: 0 | P25: 29689 | Q25: ✅
A26: 20260401 | B26: 2026 GS칼텍스 예울마루 브런치콘서트 | C26: 2026. 4. 9(목) | D26: 11:00 | E26: 926 | F26: 263 | G26: 5174000 | H26: 0 | I26: 0 | J26: 0 | K26: 263 | L26: 5174000 | M26: 0.28401728 | N26: -12 | O26: -216000 | P26: 19673 | Q26: ✅
A27: 20260401 | B27: 2026 GS칼텍스 예울마루 실내악 페스티벌 | C27: 2026. 4. 16(목) | D27: 19:30 | E27: 294 | F27: 466 | G27: 12901000 | H27: 0 | I27: 0 | J27: 0 | K27: 466 | L27: 12901000 | M27: 0.12580994 | N27: 12 | O27: 354000 | P27: 27685 | Q27: ✅
A28: 20260401 | B28: 2026 어린이 뮤지컬 <100층짜리 집> | C28: 2026. 5. 14(목) | D28: 11:00 | E28: 294 | F28: 1134 | G28: 44570400 | H28: 0 | I28: 0 | J28: 0 | K28: 1134 | L28: 44570400 | M28: 0.2038835 | N28: 17 | O28: 658700 | P28: 39304 | Q28: ✅
... A2652: 20241221 | B2652: 뮤지컬 <시카고>-여수 | C2652: 2025. 02. 16(일) | D2652: 19:30 | E2652: 3876 | F2652: 1490 | G2652: 219365000 | H2652: 84 | I2652: 11648000 | J2652: 0 | K2652: 1574 | L2652: 231013000 | M2652: 0.40608875 | N2652: 0 | O2652: 0 | P2652: 0 | Q2652: ✅
A2653: 📋 입력 미리보기 (입력창 데이터 → 누적 기록으로 변환)
A2654: ⬇ 아래 3행 선택 → Ctrl+C → 누적 기록 맨 위(행14)에 행 삽입 후 값만 붙여넣기(Ctrl+Shift+V)
A2655: =IF(OR(R5<TODAY(),F5="",F5="공연종료"),"",$B$2) | B2655: =IF(OR(R5<TODAY(),F5="",F5="공연종료"),"",B5) | C2655: =IF(OR(R5<TODAY(),F5="",F5="공연종료"),"",C5) | D2655: =IF(OR(R5<TODAY(),F5="",F5="공연종료"),"",D5) | E2655: 294 | F2655: =IF(OR(R5<TODAY(),F5="",F5="공연종료"),"",F5) | G2655: =IF(OR(R5<TODAY(),F5="",F5="공연종료"),"",G5) | H2655: =IF(OR(R5<TODAY(),F5="",F5="공연종료"),"",H5) | I2655: =IF(OR(R5<TODAY(),F5="",F5="공연종료"),"",I5) | J2655: =IF(OR(R5<TODAY(),F5="",F5="공연종료"),"",J5) | K2655: =IF(OR(R5<TODAY(),F5="",F5="공연종료"),"",K5) | L2655: =IF(OR(R5<TODAY(),F5="",F5="공연종료"),"",L5) | M2655: =IF(OR(R5<TODAY(),F5="",F5="공연종료"),"",M5) | N2655: {=IF(OR(R5<TODAY(),F5="",F5="공연종료"),"",K5-IFERROR(INDEX($K$153:$K$7593,MATCH(B5&D5,$B$153:$B$7593&$D$153:$D$7593,0)),0))} | O2655: {=IF(OR(R5<TODAY(),F5="",F5="공연종료"),"",L5-IFERROR(INDEX($L$153:$L$7593,MATCH(B5&D5,$B$153:$B$7593&$D$153:$D$7593,0)),0))} | P2655: =IF(OR(R5<TODAY(),K5=0,F5="",F5="공연종료"),"",ROUND(L5/K5,0))
A2656: =IF(OR(R6<TODAY(),F6="",F6="공연종료"),"",$B$2) | B2656: =IF(OR(R6<TODAY(),F6="",F6="공연종료"),"",B6) | C2656: =IF(OR(R6<TODAY(),F6="",F6="공연종료"),"",C6) | D2656: =IF(OR(R6<TODAY(),F6="",F6="공연종료"),"",D6) | E2656: 294 | F2656: =IF(OR(R6<TODAY(),F6="",F6="공연종료"),"",F6) | G2656: =IF(OR(R6<TODAY(),F6="",F6="공연종료"),"",G6) | H2656: =IF(OR(R6<TODAY(),F6="",F6="공연종료"),"",H6) | I2656: =IF(OR(R6<TODAY(),F6="",F6="공연종료"),"",I6) | J2656: =IF(OR(R6<TODAY(),F6="",F6="공연종료"),"",J6) | K2656: =IF(OR(R6<TODAY(),F6="",F6="공연종료"),"",K6) | L2656: =IF(OR(R6<TODAY(),F6="",F6="공연종료"),"",L6) | M2656: =IF(OR(R6<TODAY(),F6="",F6="공연종료"),"",M6) | N2656: {=IF(OR(R6<TODAY(),F6="",F6="공연종료"),"",K6-IFERROR(INDEX($K$153:$K$7593,MATCH(B6&D6,$B$153:$B$7593&$D$153:$D$7593,0)),0))} | O2656: {=IF(OR(R6<TODAY(),F6="",F6="공연종료"),"",L6-IFERROR(INDEX($L$153:$L$7593,MATCH(B6&D6,$B$153:$B$7593&$D$153:$D$7593,0)),0))} | P2656: =IF(OR(R6<TODAY(),K6=0,F6="",F6="공연종료"),"",ROUND(L6/K6,0))
A2657: =IF(OR(R7<TODAY(),F7="",F7="공연종료"),"",$B$2) | B2657: =IF(OR(R7<TODAY(),F7="",F7="공연종료"),"",B7) | C2657: =IF(OR(R7<TODAY(),F7="",F7="공연종료"),"",C7) | D2657: =IF(OR(R7<TODAY(),F7="",F7="공연종료"),"",D7) | E2657: 926 | F2657: =IF(OR(R7<TODAY(),F7="",F7="공연종료"),"",F7) | G2657: =IF(OR(R7<TODAY(),F7="",F7="공연종료"),"",G7) | H2657: =IF(OR(R7<TODAY(),F7="",F7="공연종료"),"",H7) | I2657: =IF(OR(R7<TODAY(),F7="",F7="공연종료"),"",I7) | J2657: =IF(OR(R7<TODAY(),F7="",F7="공연종료"),"",J7) | K2657: =IF(OR(R7<TODAY(),F7="",F7="공연종료"),"",K7) | L2657: =IF(OR(R7<TODAY(),F7="",F7="공연종료"),"",L7) | M2657: =IF(OR(R7<TODAY(),F7="",F7="공연종료"),"",M7) | N2657: {=IF(OR(R7<TODAY(),F7="",F7="공연종료"),"",K7-IFERROR(INDEX($K$153:$K$7593,MATCH(B7&D7,$B$153:$B$7593&$D$153:$D$7593,0)),0))} | O2657: {=IF(OR(R7<TODAY(),F7="",F7="공연종료"),"",L7-IFERROR(INDEX($L$153:$L$7593,MATCH(B7&D7,$B$153:$B$7593&$D$153:$D$7593,0)),0))} | P2657: =IF(OR(R7<TODAY(),K7=0,F7="",F7="공연종료"),"",ROUND(L7/K7,0))
A2658: ① 상단 입력창(행5~7)에 진행 중인 공연만 표시됩니다. 오늘 변경된 수치만 수정하세요
A2659: ② 수정 완료 후, 미리보기(행72~74)에서 변환된 내용을 확인합니다
A2660: ③ 미리보기 행을 복사(Ctrl+C) → 누적기록 맨 위(행14) 앞에 행 삽입 → 값만 붙여넣기
A2661: ④ 붙여넣기 후 입력창은 자동으로 최신 데이터를 다시 불러옵니다
A2662: ⚠ 같은 날짜+같은 공연이 이미 있으면 '⚠ 중복!' 표시 → 기존 누적 행을 수정하세요
A2663: 💡 과거 날짜 조회: 누적 기록 헤더(행15) 필터 버튼 → 기준일자에서 원하는 날짜 선택

Sheet 판매추이
A1: 기준일자 | B1: 공연명 | C1: 공연일 | D1: 회차/시각 | E1: 오픈석 | F1: 유료좌석 | G1: 유료금액 | H1: 예약좌석 | I1: 예약금액 | J1: 무료좌석 | K1: 합계좌석 | L1: 합계금액 | M1: 점유율 | N1: 전일대비(석) | O1: 전일대비(원) | P1: 객단가 | R1: ▶ 공연통합 | S1: 통합 합계좌석 | T1: 통합 합계금액 | U1: 회차수
A2: =IF(OR(일일입력!A17="",일일입력!F17=""),"",일일입력!A17) | B2: =IF(OR(일일입력!A17="",일일입력!F17=""),"",일일입력!B17) | C2: =IF(OR(일일입력!A17="",일일입력!F17=""),"",일일입력!C17) | D2: =IF(OR(일일입력!A17="",일일입력!F17=""),"",일일입력!D17) | E2: =IF(OR(일일입력!A17="",일일입력!F17=""),"",일일입력!E17) | F2: =IF(OR(일일입력!A17="",일일입력!F17=""),"",일일입력!F17) | G2: =IF(OR(일일입력!A17="",일일입력!F17=""),"",일일입력!G17) | H2: =IF(OR(일일입력!A17="",일일입력!F17=""),"",일일입력!H17) | I2: =IF(OR(일일입력!A17="",일일입력!F17=""),"",일일입력!I17) | J2: =IF(OR(일일입력!A17="",일일입력!F17=""),"",일일입력!J17) | K2: =IF(OR(일일입력!A17="",일일입력!F17=""),"",일일입력!K17) | L2: =IF(OR(일일입력!A17="",일일입력!F17=""),"",일일입력!L17) | M2: =IF(OR(일일입력!A17="",일일입력!F17=""),"",일일입력!M17) | N2: =IF(OR(일일입력!A17="",일일입력!F17=""),"",일일입력!N17) | O2: =IF(OR(일일입력!A17="",일일입력!F17=""),"",일일입력!O17) | P2: =IF(OR(일일입력!A17="",일일입력!F17=""),"",일일입력!P17) | R2: =IF(A2="","",IF(COUNTIFS($A$2:$A$2501,A2,$B$2:$B$2501,B2)>1,"● 통합","")) | S2: =IF(A2="","",SUMIFS($K$2:$K$2501,$A$2:$A$2501,A2,$B$2:$B$2501,B2)) | T2: =IF(A2="","",SUMIFS($L$2:$L$2501,$A$2:$A$2501,A2,$B$2:$B$2501,B2)) | U2: =IF(A2="","",COUNTIFS($A$2:$A$2501,A2,$B$2:$B$2501,B2))
A3: =IF(OR(일일입력!A18="",일일입력!F18=""),"",일일입력!A18) | B3: =IF(OR(일일입력!A18="",일일입력!F18=""),"",일일입력!B18) | C3: =IF(OR(일일입력!A18="",일일입력!F18=""),"",일일입력!C18) | D3: =IF(OR(일일입력!A18="",일일입력!F18=""),"",일일입력!D18) | E3: =IF(OR(일일입력!A18="",일일입력!F18=""),"",일일입력!E18) | F3: =IF(OR(일일입력!A18="",일일입력!F18=""),"",일일입력!F18) | G3: =IF(OR(일일입력!A18="",일일입력!F18=""),"",일일입력!G18) | H3: =IF(OR(일일입력!A18="",일일입력!F18=""),"",일일입력!H18) | I3: =IF(OR(일일입력!A18="",일일입력!F18=""),"",일일입력!I18) | J3: =IF(OR(일일입력!A18="",일일입력!F18=""),"",일일입력!J18) | K3: =IF(OR(일일입력!A18="",일일입력!F18=""),"",일일입력!K18) | L3: =IF(OR(일일입력!A18="",일일입력!F18=""),"",일일입력!L18) | M3: =IF(OR(일일입력!A18="",일일입력!F18=""),"",일일입력!M18) | N3: =IF(OR(일일입력!A18="",일일입력!F18=""),"",일일입력!N18) | O3: =IF(OR(일일입력!A18="",일일입력!F18=""),"",일일입력!O18) | P3: =IF(OR(일일입력!A18="",일일입력!F18=""),"",일일입력!P18) | R3: =IF(A3="","",IF(COUNTIFS($A$2:$A$2501,A3,$B$2:$B$2501,B3)>1,"● 통합","")) | S3: =IF(A3="","",SUMIFS($K$2:$K$2501,$A$2:$A$2501,A3,$B$2:$B$2501,B3)) | T3: =IF(A3="","",SUMIFS($L$2:$L$2501,$A$2:$A$2501,A3,$B$2:$B$2501,B3)) | U3: =IF(A3="","",COUNTIFS($A$2:$A$2501,A3,$B$2:$B$2501,B3))
A4: =IF(OR(일일입력!A19="",일일입력!F19=""),"",일일입력!A19) | B4: =IF(OR(일일입력!A19="",일일입력!F19=""),"",일일입력!B19) | C4: =IF(OR(일일입력!A19="",일일입력!F19=""),"",일일입력!C19) | D4: =IF(OR(일일입력!A19="",일일입력!F19=""),"",일일입력!D19) | E4: =IF(OR(일일입력!A19="",일일입력!F19=""),"",일일입력!E19) | F4: =IF(OR(일일입력!A19="",일일입력!F19=""),"",일일입력!F19) | G4: =IF(OR(일일입력!A19="",일일입력!F19=""),"",일일입력!G19) | H4: =IF(OR(일일입력!A19="",일일입력!F19=""),"",일일입력!H19) | I4: =IF(OR(일일입력!A19="",일일입력!F19=""),"",일일입력!I19) | J4: =IF(OR(일일입력!A19="",일일입력!F19=""),"",일일입력!J19) | K4: =IF(OR(일일입력!A19="",일일입력!F19=""),"",일일입력!K19) | L4: =IF(OR(일일입력!A19="",일일입력!F19=""),"",일일입력!L19) | M4: =IF(OR(일일입력!A19="",일일입력!F19=""),"",일일입력!M19) | N4: =IF(OR(일일입력!A19="",일일입력!F19=""),"",일일입력!N19) | O4: =IF(OR(일일입력!A19="",일일입력!F19=""),"",일일입력!O19) | P4: =IF(OR(일일입력!A19="",일일입력!F19=""),"",일일입력!P19) | R4: =IF(A4="","",IF(COUNTIFS($A$2:$A$2501,A4,$B$2:$B$2501,B4)>1,"● 통합","")) | S4: =IF(A4="","",SUMIFS($K$2:$K$2501,$A$2:$A$2501,A4,$B$2:$B$2501,B4)) | T4: =IF(A4="","",SUMIFS($L$2:$L$2501,$A$2:$A$2501,A4,$B$2:$B$2501,B4)) | U4: =IF(A4="","",COUNTIFS($A$2:$A$2501,A4,$B$2:$B$2501,B4))
A5: =IF(OR(일일입력!A20="",일일입력!F20=""),"",일일입력!A20) | B5: =IF(OR(일일입력!A20="",일일입력!F20=""),"",일일입력!B20) | C5: =IF(OR(일일입력!A20="",일일입력!F20=""),"",일일입력!C20) | D5: =IF(OR(일일입력!A20="",일일입력!F20=""),"",일일입력!D20) | E5: =IF(OR(일일입력!A20="",일일입력!F20=""),"",일일입력!E20) | F5: =IF(OR(일일입력!A20="",일일입력!F20=""),"",일일입력!F20) | G5: =IF(OR(일일입력!A20="",일일입력!F20=""),"",일일입력!G20) | H5: =IF(OR(일일입력!A20="",일일입력!F20=""),"",일일입력!H20) | I5: =IF(OR(일일입력!A20="",일일입력!F20=""),"",일일입력!I20) | J5: =IF(OR(일일입력!A20="",일일입력!F20=""),"",일일입력!J20) | K5: =IF(OR(일일입력!A20="",일일입력!F20=""),"",일일입력!K20) | L5: =IF(OR(일일입력!A20="",일일입력!F20=""),"",일일입력!L20) | M5: =IF(OR(일일입력!A20="",일일입력!F20=""),"",일일입력!M20) | N5: =IF(OR(일일입력!A20="",일일입력!F20=""),"",일일입력!N20) | O5: =IF(OR(일일입력!A20="",일일입력!F20=""),"",일일입력!O20) | P5: =IF(OR(일일입력!A20="",일일입력!F20=""),"",일일입력!P20) | R5: =IF(A5="","",IF(COUNTIFS($A$2:$A$2501,A5,$B$2:$B$2501,B5)>1,"● 통합","")) | S5: =IF(A5="","",SUMIFS($K$2:$K$2501,$A$2:$A$2501,A5,$B$2:$B$2501,B5)) | T5: =IF(A5="","",SUMIFS($L$2:$L$2501,$A$2:$A$2501,A5,$B$2:$B$2501,B5)) | U5: =IF(A5="","",COUNTIFS($A$2:$A$2501,A5,$B$2:$B$2501,B5))
A6: =IF(OR(일일입력!A21="",일일입력!F21=""),"",일일입력!A21) | B6: =IF(OR(일일입력!A21="",일일입력!F21=""),"",일일입력!B21) | C6: =IF(OR(일일입력!A21="",일일입력!F21=""),"",일일입력!C21) | D6: =IF(OR(일일입력!A21="",일일입력!F21=""),"",일일입력!D21) | E6: =IF(OR(일일입력!A21="",일일입력!F21=""),"",일일입력!E21) | F6: =IF(OR(일일입력!A21="",일일입력!F21=""),"",일일입력!F21) | G6: =IF(OR(일일입력!A21="",일일입력!F21=""),"",일일입력!G21) | H6: =IF(OR(일일입력!A21="",일일입력!F21=""),"",일일입력!H21) | I6: =IF(OR(일일입력!A21="",일일입력!F21=""),"",일일입력!I21) | J6: =IF(OR(일일입력!A21="",일일입력!F21=""),"",일일입력!J21) | K6: =IF(OR(일일입력!A21="",일일입력!F21=""),"",일일입력!K21) | L6: =IF(OR(일일입력!A21="",일일입력!F21=""),"",일일입력!L21) | M6: =IF(OR(일일입력!A21="",일일입력!F21=""),"",일일입력!M21) | N6: =IF(OR(일일입력!A21="",일일입력!F21=""),"",일일입력!N21) | O6: =IF(OR(일일입력!A21="",일일입력!F21=""),"",일일입력!O21) | P6: =IF(OR(일일입력!A21="",일일입력!F21=""),"",일일입력!P21) | R6: =IF(A6="","",IF(COUNTIFS($A$2:$A$2501,A6,$B$2:$B$2501,B6)>1,"● 통합","")) | S6: =IF(A6="","",SUMIFS($K$2:$K$2501,$A$2:$A$2501,A6,$B$2:$B$2501,B6)) | T6: =IF(A6="","",SUMIFS($L$2:$L$2501,$A$2:$A$2501,A6,$B$2:$B$2501,B6)) | U6: =IF(A6="","",COUNTIFS($A$2:$A$2501,A6,$B$2:$B$2501,B6))
A7: =IF(OR(일일입력!A22="",일일입력!F22=""),"",일일입력!A22) | B7: =IF(OR(일일입력!A22="",일일입력!F22=""),"",일일입력!B22) | C7: =IF(OR(일일입력!A22="",일일입력!F22=""),"",일일입력!C22) | D7: =IF(OR(일일입력!A22="",일일입력!F22=""),"",일일입력!D22) | E7: =IF(OR(일일입력!A22="",일일입력!F22=""),"",일일입력!E22) | F7: =IF(OR(일일입력!A22="",일일입력!F22=""),"",일일입력!F22) | G7: =IF(OR(일일입력!A22="",일일입력!F22=""),"",일일입력!G22) | H7: =IF(OR(일일입력!A22="",일일입력!F22=""),"",일일입력!H22) | I7: =IF(OR(일일입력!A22="",일일입력!F22=""),"",일일입력!I22) | J7: =IF(OR(일일입력!A22="",일일입력!F22=""),"",일일입력!J22) | K7: =IF(OR(일일입력!A22="",일일입력!F22=""),"",일일입력!K22) | L7: =IF(OR(일일입력!A22="",일일입력!F22=""),"",일일입력!L22) | M7: =IF(OR(일일입력!A22="",일일입력!F22=""),"",일일입력!M22) | N7: =IF(OR(일일입력!A22="",일일입력!F22=""),"",일일입력!N22) | O7: =IF(OR(일일입력!A22="",일일입력!F22=""),"",일일입력!O22) | P7: =IF(OR(일일입력!A22="",일일입력!F22=""),"",일일입력!P22) | R7: =IF(A7="","",IF(COUNTIFS($A$2:$A$2501,A7,$B$2:$B$2501,B7)>1,"● 통합","")) | S7: =IF(A7="","",SUMIFS($K$2:$K$2501,$A$2:$A$2501,A7,$B$2:$B$2501,B7)) | T7: =IF(A7="","",SUMIFS($L$2:$L$2501,$A$2:$A$2501,A7,$B$2:$B$2501,B7)) | U7: =IF(A7="","",COUNTIFS($A$2:$A$2501,A7,$B$2:$B$2501,B7))
A8: =IF(OR(일일입력!A23="",일일입력!F23=""),"",일일입력!A23) | B8: =IF(OR(일일입력!A23="",일일입력!F23=""),"",일일입력!B23) | C8: =IF(OR(일일입력!A23="",일일입력!F23=""),"",일일입력!C23) | D8: =IF(OR(일일입력!A23="",일일입력!F23=""),"",일일입력!D23) | E8: =IF(OR(일일입력!A23="",일일입력!F23=""),"",일일입력!E23) | F8: =IF(OR(일일입력!A23="",일일입력!F23=""),"",일일입력!F23) | G8: =IF(OR(일일입력!A23="",일일입력!F23=""),"",일일입력!G23) | H8: =IF(OR(일일입력!A23="",일일입력!F23=""),"",일일입력!H23) | I8: =IF(OR(일일입력!A23="",일일입력!F23=""),"",일일입력!I23) | J8: =IF(OR(일일입력!A23="",일일입력!F23=""),"",일일입력!J23) | K8: =IF(OR(일일입력!A23="",일일입력!F23=""),"",일일입력!K23) | L8: =IF(OR(일일입력!A23="",일일입력!F23=""),"",일일입력!L23) | M8: =IF(OR(일일입력!A23="",일일입력!F23=""),"",일일입력!M23) | N8: =IF(OR(일일입력!A23="",일일입력!F23=""),"",일일입력!N23) | O8: =IF(OR(일일입력!A23="",일일입력!F23=""),"",일일입력!O23) | P8: =IF(OR(일일입력!A23="",일일입력!F23=""),"",일일입력!P23) | R8: =IF(A8="","",IF(COUNTIFS($A$2:$A$2501,A8,$B$2:$B$2501,B8)>1,"● 통합","")) | S8: =IF(A8="","",SUMIFS($K$2:$K$2501,$A$2:$A$2501,A8,$B$2:$B$2501,B8)) | T8: =IF(A8="","",SUMIFS($L$2:$L$2501,$A$2:$A$2501,A8,$B$2:$B$2501,B8)) | U8: =IF(A8="","",COUNTIFS($A$2:$A$2501,A8,$B$2:$B$2501,B8))
A9: =IF(OR(일일입력!A24="",일일입력!F24=""),"",일일입력!A24) | B9: =IF(OR(일일입력!A24="",일일입력!F24=""),"",일일입력!B24) | C9: =IF(OR(일일입력!A24="",일일입력!F24=""),"",일일입력!C24) | D9: =IF(OR(일일입력!A24="",일일입력!F24=""),"",일일입력!D24) | E9: =IF(OR(일일입력!A24="",일일입력!F24=""),"",일일입력!E24) | F9: =IF(OR(일일입력!A24="",일일입력!F24=""),"",일일입력!F24) | G9: =IF(OR(일일입력!A24="",일일입력!F24=""),"",일일입력!G24) | H9: =IF(OR(일일입력!A24="",일일입력!F24=""),"",일일입력!H24) | I9: =IF(OR(일일입력!A24="",일일입력!F24=""),"",일일입력!I24) | J9: =IF(OR(일일입력!A24="",일일입력!F24=""),"",일일입력!J24) | K9: =IF(OR(일일입력!A24="",일일입력!F24=""),"",일일입력!K24) | L9: =IF(OR(일일입력!A24="",일일입력!F24=""),"",일일입력!L24) | M9: =IF(OR(일일입력!A24="",일일입력!F24=""),"",일일입력!M24) | N9: =IF(OR(일일입력!A24="",일일입력!F24=""),"",일일입력!N24) | O9: =IF(OR(일일입력!A24="",일일입력!F24=""),"",일일입력!O24) | P9: =IF(OR(일일입력!A24="",일일입력!F24=""),"",일일입력!P24) | R9: =IF(A9="","",IF(COUNTIFS($A$2:$A$2501,A9,$B$2:$B$2501,B9)>1,"● 통합","")) | S9: =IF(A9="","",SUMIFS($K$2:$K$2501,$A$2:$A$2501,A9,$B$2:$B$2501,B9)) | T9: =IF(A9="","",SUMIFS($L$2:$L$2501,$A$2:$A$2501,A9,$B$2:$B$2501,B9)) | U9: =IF(A9="","",COUNTIFS($A$2:$A$2501,A9,$B$2:$B$2501,B9))
A10: =IF(OR(일일입력!A25="",일일입력!F25=""),"",일일입력!A25) | B10: =IF(OR(일일입력!A25="",일일입력!F25=""),"",일일입력!B25) | C10: =IF(OR(일일입력!A25="",일일입력!F25=""),"",일일입력!C25) | D10: =IF(OR(일일입력!A25="",일일입력!F25=""),"",일일입력!D25) | E10: =IF(OR(일일입력!A25="",일일입력!F25=""),"",일일입력!E25) | F10: =IF(OR(일일입력!A25="",일일입력!F25=""),"",일일입력!F25) | G10: =IF(OR(일일입력!A25="",일일입력!F25=""),"",일일입력!G25) | H10: =IF(OR(일일입력!A25="",일일입력!F25=""),"",일일입력!H25) | I10: =IF(OR(일일입력!A25="",일일입력!F25=""),"",일일입력!I25) | J10: =IF(OR(일일입력!A25="",일일입력!F25=""),"",일일입력!J25) | K10: =IF(OR(일일입력!A25="",일일입력!F25=""),"",일일입력!K25) | L10: =IF(OR(일일입력!A25="",일일입력!F25=""),"",일일입력!L25) | M10: =IF(OR(일일입력!A25="",일일입력!F25=""),"",일일입력!M25) | N10: =IF(OR(일일입력!A25="",일일입력!F25=""),"",일일입력!N25) | O10: =IF(OR(일일입력!A25="",일일입력!F25=""),"",일일입력!O25) | P10: =IF(OR(일일입력!A25="",일일입력!F25=""),"",일일입력!P25) | R10: =IF(A10="","",IF(COUNTIFS($A$2:$A$2501,A10,$B$2:$B$2501,B10)>1,"● 통합","")) | S10: =IF(A10="","",SUMIFS($K$2:$K$2501,$A$2:$A$2501,A10,$B$2:$B$2501,B10)) | T10: =IF(A10="","",SUMIFS($L$2:$L$2501,$A$2:$A$2501,A10,$B$2:$B$2501,B10)) | U10: =IF(A10="","",COUNTIFS($A$2:$A$2501,A10,$B$2:$B$2501,B10))
A11: =IF(OR(일일입력!A26="",일일입력!F26=""),"",일일입력!A26) | B11: =IF(OR(일일입력!A26="",일일입력!F26=""),"",일일입력!B26) | C11: =IF(OR(일일입력!A26="",일일입력!F26=""),"",일일입력!C26) | D11: =IF(OR(일일입력!A26="",일일입력!F26=""),"",일일입력!D26) | E11: =IF(OR(일일입력!A26="",일일입력!F26=""),"",일일입력!E26) | F11: =IF(OR(일일입력!A26="",일일입력!F26=""),"",일일입력!F26) | G11: =IF(OR(일일입력!A26="",일일입력!F26=""),"",일일입력!G26) | H11: =IF(OR(일일입력!A26="",일일입력!F26=""),"",일일입력!H26) | I11: =IF(OR(일일입력!A26="",일일입력!F26=""),"",일일입력!I26) | J11: =IF(OR(일일입력!A26="",일일입력!F26=""),"",일일입력!J26) | K11: =IF(OR(일일입력!A26="",일일입력!F26=""),"",일일입력!K26) | L11: =IF(OR(일일입력!A26="",일일입력!F26=""),"",일일입력!L26) | M11: =IF(OR(일일입력!A26="",일일입력!F26=""),"",일일입력!M26) | N11: =IF(OR(일일입력!A26="",일일입력!F26=""),"",일일입력!N26) | O11: =IF(OR(일일입력!A26="",일일입력!F26=""),"",일일입력!O26) | P11: =IF(OR(일일입력!A26="",일일입력!F26=""),"",일일입력!P26) | R11: =IF(A11="","",IF(COUNTIFS($A$2:$A$2501,A11,$B$2:$B$2501,B11)>1,"● 통합","")) | S11: =IF(A11="","",SUMIFS($K$2:$K$2501,$A$2:$A$2501,A11,$B$2:$B$2501,B11)) | T11: =IF(A11="","",SUMIFS($L$2:$L$2501,$A$2:$A$2501,A11,$B$2:$B$2501,B11)) | U11: =IF(A11="","",COUNTIFS($A$2:$A$2501,A11,$B$2:$B$2501,B11))
A12: =IF(OR(일일입력!A27="",일일입력!F27=""),"",일일입력!A27) | B12: =IF(OR(일일입력!A27="",일일입력!F27=""),"",일일입력!B27) | C12: =IF(OR(일일입력!A27="",일일입력!F27=""),"",일일입력!C27) | D12: =IF(OR(일일입력!A27="",일일입력!F27=""),"",일일입력!D27) | E12: =IF(OR(일일입력!A27="",일일입력!F27=""),"",일일입력!E27) | F12: =IF(OR(일일입력!A27="",일일입력!F27=""),"",일일입력!F27) | G12: =IF(OR(일일입력!A27="",일일입력!F27=""),"",일일입력!G27) | H12: =IF(OR(일일입력!A27="",일일입력!F27=""),"",일일입력!H27) | I12: =IF(OR(일일입력!A27="",일일입력!F27=""),"",일일입력!I27) | J12: =IF(OR(일일입력!A27="",일일입력!F27=""),"",일일입력!J27) | K12: =IF(OR(일일입력!A27="",일일입력!F27=""),"",일일입력!K27) | L12: =IF(OR(일일입력!A27="",일일입력!F27=""),"",일일입력!L27) | M12: =IF(OR(일일입력!A27="",일일입력!F27=""),"",일일입력!M27) | N12: =IF(OR(일일입력!A27="",일일입력!F27=""),"",일일입력!N27) | O12: =IF(OR(일일입력!A27="",일일입력!F27=""),"",일일입력!O27) | P12: =IF(OR(일일입력!A27="",일일입력!F27=""),"",일일입력!P27) | R12: =IF(A12="","",IF(COUNTIFS($A$2:$A$2501,A12,$B$2:$B$2501,B12)>1,"● 통합","")) | S12: =IF(A12="","",SUMIFS($K$2:$K$2501,$A$2:$A$2501,A12,$B$2:$B$2501,B12)) | T12: =IF(A12="","",SUMIFS($L$2:$L$2501,$A$2:$A$2501,A12,$B$2:$B$2501,B12)) | U12: =IF(A12="","",COUNTIFS($A$2:$A$2501,A12,$B$2:$B$2501,B12))
A13: =IF(OR(일일입력!A28="",일일입력!F28=""),"",일일입력!A28) | B13: =IF(OR(일일입력!A28="",일일입력!F28=""),"",일일입력!B28) | C13: =IF(OR(일일입력!A28="",일일입력!F28=""),"",일일입력!C28) | D13: =IF(OR(일일입력!A28="",일일입력!F28=""),"",일일입력!D28) | E13: =IF(OR(일일입력!A28="",일일입력!F28=""),"",일일입력!E28) | F13: =IF(OR(일일입력!A28="",일일입력!F28=""),"",일일입력!F28) | G13: =IF(OR(일일입력!A28="",일일입력!F28=""),"",일일입력!G28) | H13: =IF(OR(일일입력!A28="",일일입력!F28=""),"",일일입력!H28) | I13: =IF(OR(일일입력!A28="",일일입력!F28=""),"",일일입력!I28) | J13: =IF(OR(일일입력!A28="",일일입력!F28=""),"",일일입력!J28) | K13: =IF(OR(일일입력!A28="",일일입력!F28=""),"",일일입력!K28) | L13: =IF(OR(일일입력!A28="",일일입력!F28=""),"",일일입력!L28) | M13: =IF(OR(일일입력!A28="",일일입력!F28=""),"",일일입력!M28) | N13: =IF(OR(일일입력!A28="",일일입력!F28=""),"",일일입력!N28) | O13: =IF(OR(일일입력!A28="",일일입력!F28=""),"",일일입력!O28) | P13: =IF(OR(일일입력!A28="",일일입력!F28=""),"",일일입력!P28) | R13: =IF(A13="","",IF(COUNTIFS($A$2:$A$2501,A13,$B$2:$B$2501,B13)>1,"● 통합","")) | S13: =IF(A13="","",SUMIFS($K$2:$K$2501,$A$2:$A$2501,A13,$B$2:$B$2501,B13)) | T13: =IF(A13="","",SUMIFS($L$2:$L$2501,$A$2:$A$2501,A13,$B$2:$B$2501,B13)) | U13: =IF(A13="","",COUNTIFS($A$2:$A$2501,A13,$B$2:$B$2501,B13))
... A2501: =IF(OR(일일입력!A2516="",일일입력!F2516=""),"",일일입력!A2516) | B2501: =IF(OR(일일입력!A2516="",일일입력!F2516=""),"",일일입력!B2516) | C2501: =IF(OR(일일입력!A2516="",일일입력!F2516=""),"",일일입력!C2516) | D2501: =IF(OR(일일입력!A2516="",일일입력!F2516=""),"",일일입력!D2516) | E2501: =IF(OR(일일입력!A2516="",일일입력!F2516=""),"",일일입력!E2516) | F2501: =IF(OR(일일입력!A2516="",일일입력!F2516=""),"",일일입력!F2516) | G2501: =IF(OR(일일입력!A2516="",일일입력!F2516=""),"",일일입력!G2516) | H2501: =IF(OR(일일입력!A2516="",일일입력!F2516=""),"",일일입력!H2516) | I2501: =IF(OR(일일입력!A2516="",일일입력!F2516=""),"",일일입력!I2516) | J2501: =IF(OR(일일입력!A2516="",일일입력!F2516=""),"",일일입력!J2516) | K2501: =IF(OR(일일입력!A2516="",일일입력!F2516=""),"",일일입력!K2516) | L2501: =IF(OR(일일입력!A2516="",일일입력!F2516=""),"",일일입력!L2516) | M2501: =IF(OR(일일입력!A2516="",일일입력!F2516=""),"",일일입력!M2516) | N2501: =IF(OR(일일입력!A2516="",일일입력!F2516=""),"",일일입력!N2516) | O2501: =IF(OR(일일입력!A2516="",일일입력!F2516=""),"",일일입력!O2516) | P2501: =IF(OR(일일입력!A2516="",일일입력!F2516=""),"",일일입력!P2516) | R2501: =IF(A2501="","",IF(COUNTIFS($A$2:$A$2501,A2501,$B$2:$B$2501,B2501)>1,"● 통합","")) | S2501: =IF(A2501="","",SUMIFS($K$2:$K$2501,$A$2:$A$2501,A2501,$B$2:$B$2501,B2501)) | T2501: =IF(A2501="","",SUMIFS($L$2:$L$2501,$A$2:$A$2501,A2501,$B$2:$B$2501,B2501)) | U2501: =IF(A2501="","",COUNTIFS($A$2:$A$2501,A2501,$B$2:$B$2501,B2501))
A2502: ※ 이 시트는 '일일입력' 시트의 데이터를 자동 참조합니다. 새 데이터는 '일일입력' 시트에 추가하세요. (최대 2,500행)

Sheet 운영실적통합
A1: GS칼텍스 예울마루 운영실적 통합
A3: ▣ 연도별 공연 종합실적
A4: 구분 | B4: 기간 | C4: 공연횟수 | D4: 공연일수 | E4: 관람인원
A5: 2012년 | B5: 5월 ~ 12월 | C5: 85 | D5: 77 | E5: 57418
A6: 2013년 | B6: 1월 ~ 12월 | C6: 169 | D6: 143 | E6: 101534
A7: 2014년 | B7: 1월 ~ 12월 | C7: 162 | D7: 145 | E7: 73021
A8: 2015년 | B8: 1월 ~ 12월 | C8: 180 | D8: 154 | E8: 74875
A9: 2016년 | B9: 1월 ~ 12월 | C9: 151 | D9: 127 | E9: 77070
A10: 2017년 | B10: 1월 ~ 12월 | C10: 131 | D10: 111 | E10: 67004
A11: 2018년 | B11: 1월 ~ 12월 | C11: 124 | D11: 99 | E11: 66864
A12: 2019년 | B12: 1월 ~ 12월 | C12: 154 | D12: 116 | E12: 78506
A13: 2020년 | B13: 1월 ~ 12월 | C13: 61 | D13: 51 | E13: 17769
A14: 2021년 | B14: 1월 ~ 12월 | C14: 141 | D14: 99 | E14: 38543
A15: 2022년 | B15: 1월 ~ 12월 | C15: 184 | D15: 125 | E15: 74322
A16: 2023년 | B16: 1월 ~ 12월 | C16: 200 | D16: 128 | E16: 81048
... A19: 2026년 | B19: 1월 ~ 12월 | C19: 5 | D19: 3 | E19: 4266
A20: 합계 | C20: =SUM(C5:C19) | D20: =SUM(D5:D19) | E20: =SUM(E5:E19)
A22: ▣ 연도별 문화나눔 실적
A23: 구분 | B23: 기간 | C23: 공연(명) | D23: 전시(명) | E23: 소계(명)
A24: 2012년 | B24: 5월 ~ 12월 | C24: 1102 | D24: 430 | E24: =C24+D24
A25: 2013년 | B25: 1월 ~ 12월 | C25: 1347 | D25: 4381 | E25: =C25+D25
A26: 2014년 | B26: 1월 ~ 12월 | C26: 697 | D26: 1151 | E26: =C26+D26
A27: 2015년 | B27: 1월 ~ 12월 | C27: 592 | D27: 652 | E27: =C27+D27
A28: 2016년 | B28: 1월 ~ 12월 | C28: 513 | D28: 839 | E28: =C28+D28
A29: 2017년 | B29: 1월 ~ 12월 | C29: 624 | D29: 961 | E29: =C29+D29
A30: 2018년 | B30: 1월 ~ 12월 | C30: 430 | D30: 1062 | E30: =C30+D30
A31: 2019년 | B31: 1월 ~ 12월 | C31: 612 | D31: 823 | E31: =C31+D31
A32: 2020년 | B32: 1월 ~ 12월 | C32: 0 | D32: 264 | E32: =C32+D32
A33: 2021년 | B33: 1월 ~ 12월 | C33: 0 | D33: 0 | E33: =C33+D33
A34: 2022년 | B34: 1월 ~ 12월 | C34: 2000 | D34: 0 | E34: =C34+D34
A35: 2023년 | B35: 1월 ~ 12월 | C35: 129 | D35: 125 | E35: =C35+D35
... A37: 2025년 | B37: 1월 ~ 12월 | C37: 354 | D37: 211 | E37: =C37+D37
A38: 합계 | C38: =SUM(C24:C37) | D38: =SUM(D24:D37) | E38: =SUM(E24:E37)
A40: ▣ 월별 공연 상세실적
B41: 2023년 | E41: 2024년 | H41: 2025년 | K41: 2026년
A42: 월 | B42: 공연횟수 | C42: 공연일수 | D42: 관람인원 | E42: 공연횟수 | F42: 공연일수 | G42: 관람인원 | H42: 공연횟수 | I42: 공연일수 | J42: 관람인원 | K42: 공연횟수 | L42: 공연일수 | M42: 관람인원
A43: 1월 | B43: 2 | C43: 2 | D43: 1043 | E43: 2 | F43: 2 | G43: 1056 | H43: 9 | I43: 5 | J43: 2980 | K43: 5 | L43: 3 | M43: 4266
A44: 2월 | B44: 5 | C44: 5 | D44: 2015 | E44: 2 | F44: 2 | G44: 1605 | H44: 9 | I44: 6 | J44: 5276
A45: 3월 | B45: 13 | C45: 7 | D45: 4693 | E45: 9 | F45: 5 | G45: 3123 | H45: 7 | I45: 7 | J45: 3025
A46: 4월 | B46: 23 | C46: 13 | D46: 11513 | E46: 7 | F46: 6 | G46: 2620 | H46: 12 | I46: 7 | J46: 4042
...

Sheet 세부운영관리대장(정리)
A1: GS칼텍스 예울마루 공연장 운영실적 — 세부내역 (정리본) | V1: 연차보고서 공연실적
A2: 전체 순번 | B2: 건수 | C2: 년도 | D2: 월 | E2: 일 | F2: 요일 | G2: 시간 | H2: 공연명 | I2: 사업 구분 | J2: 공연 구분 | K2: 장르 | L2: 세부 장르 | M2: 공연 장소 | N2: 기본 좌석 | O2: 티켓 구분 | P2: 발권 유료 | Q2: 발권 초대 | R2: 합계 | S2: 수표 유료 | T2: 수표 초대 | U2: 합계 | V2: 공연횟수 | W2: 공연일수 | X2: 공연유료 | Y2: 공연무료 | Z2: 공연인원합 | AA2: 티켓나눔
A3: 1 | B3: 1 | C3: 2012 | D3: 5 | E3: 10 | F3: 목 | G3: 0.79166667 | H3: 예울마루 개관기념 KBS열린음악회 | I3: 공연 | J3: 기획 | K3: 대중 | L3: 기타 | M3: 야외 | N3: 6000 | O3: 무료 | P3: 0 | Q3: 6000 | R3: =P3+Q3 | S3: 0 | T3: 6000 | U3: =S3+T3
A4: 2 | B4: 2 | C4: 2012년 | D4: 5 | E4: 21 | F4: 월 | G4: 0.8125 | H4: 여수엑스포심포니오케스트라왈츠콘서트 | I4: 공연 | J4: 대관 | K4: 순수 | L4: 클래식 | M4: 대극장 | N4: 948 | O4: 무료 | P4: 0 | Q4: 720 | R4: =P4+Q4 | S4: 0 | T4: 700 | U4: =S4+T4
A5: 3 | B5: 3 | C5: 2012년 | D5: 5 | E5: 22 | F5: 화 | G5: 0.8125 | H5: 여수시립합창단 제61회 정기연주회 | I5: 공연 | J5: 대관 | K5: 순수 | L5: 클래식 | M5: 대극장 | N5: 1021 | O5: 유료 | P5: 996 | Q5: 0 | R5: =P5+Q5 | S5: 969 | T5: 0 | U5: =S5+T5
A6: 소계 | B6: 3 | C6: 2012년 | D6: 5 | E6: 3 | N6: =SUM(N3:N5) | P6: =SUM(P3:P5) | Q6: =SUM(Q3:Q5) | R6: =SUM(R3:R5) | S6: =SUM(S3:S5) | T6: =SUM(T3:T5) | U6: =SUM(U3:U5) | V6: 3 | W6: 3 | X6: 996 | Y6: 6720 | Z6: =X6+Y6
A7: 4 | B7: 1 | C7: 2012년 | D7: 6 | E7: 1 | F7: 금 | G7: 0.8125 | H7: 창작오페라<손양원> | I7: 공연 | J7: 대관 | K7: 복합 | L7: 오페라 | M7: 대극장 | N7: =948 | O7: 유료 | P7: 650 | Q7: 0 | R7: =P7+Q7 | S7: 600 | T7: 34 | U7: =S7+T7
A8: 5 | B8: 2 | C8: 2012년 | D8: 6 | E8: 2 | F8: 토 | G8: 0.58333333 | H8: 창작오페라<손양원> | I8: 공연 | J8: 대관 | K8: 복합 | L8: 오페라 | M8: 대극장 | N8: =948 | O8: 유료 | P8: 450 | Q8: 0 | R8: =P8+Q8 | S8: 380 | T8: 34 | U8: =S8+T8
A9: 6 | B9: 3 | C9: 2012년 | D9: 6 | E9: 2 | F9: 토 | G9: 0.8125 | H9: 창작오페라<손양원> | I9: 공연 | J9: 대관 | K9: 복합 | L9: 오페라 | M9: 대극장 | N9: =948 | O9: 유료 | P9: 550 | Q9: 0 | R9: =P9+Q9 | S9: 417 | T9: 33 | U9: =S9+T9
A10: 7 | B10: 4 | D10: 6 | E10: 9 | F10: 토 | G10: 0.79166667 | H10: 한중연합오케스트라 | I10: 공연 | J10: 기획 | K10: 순수 | L10: 클래식 | M10: 대극장 | N10: =948 | O10: 유료 | P10: 930 | Q10: 0 | R10: =P10+Q10 | S10: 799 | T10: 0 | U10: =S10+T10
A11: 8 | B11: 5 | C11: 2012년 | D11: 6 | E11: 10 | F11: 일 | G11: 0.625 | H11: 한-요르단 수교 50주년 기념] 요르단 국립민속예술단 | I11: 공연 | J11: 대관 | K11: 순수 | L11: 무용 | M11: 소극장 | N11: 302 | O11: 무료 | P11: 0 | Q11: 261 | R11: =P11+Q11 | S11: 0 | T11: 241 | U11: =S11+T11
A12: 9 | B12: 6 | C12: 2012년 | D12: 6 | E12: 14 | F12: 목 | G12: 0.8125 | H12: 창작오페라<귀항>_2012 | I12: 공연 | J12: 대관 | K12: 복합 | L12: 오페라 | M12: 대극장 | N12: =948 | O12: 유료 | P12: 631 | Q12: 56 | R12: =P12+Q12 | S12: 585 | T12: 82 | U12: =S12+T12
A13: 10 | B13: 7 | C13: 2012년 | D13: 6 | E13: 15 | F13: 금 | G13: 0.8125 | H13: 창작오페라<귀항>_2012 | I13: 공연 | J13: 대관 | K13: 복합 | L13: 오페라 | M13: 대극장 | N13: =948 | O13: 유료 | P13: 635 | Q13: 109 | R13: =P13+Q13 | S13: 585 | T13: 82 | U13: =S13+T13
A14: 11 | B14: 8 | C14: 2012년 | D14: 6 | E14: 16 | F14: 토 | G14: 0.8125 | H14: 창작오페라<귀항>_2012 | I14: 공연 | J14: 대관 | K14: 복합 | L14: 오페라 | M14: 대극장 | N14: =948 | O14: 유료 | P14: 598 | Q14: 128 | R14: =P14+Q14 | S14: 584 | T14: 82 | U14: =S14+T14
A15: 12 | B15: 9 | C15: 2012년 | D15: 6 | E15: 17 | F15: 토 | G15: 0.8125 | H15: [한-모로코 수교 50주년 기념] 모로코 라바트 안달루시아 오케스트라 | I15: 공연 | J15: 대관 | K15: 순수 | L15: 클래식 | M15: 소극장 | N15: 302 | O15: 무료 | P15: 0 | Q15: 226 | R15: =P15+Q15 | S15: 0 | T15: 196 | U15: =S15+T15
A16: 13 | B16: 10 | C16: 2012년 | D16: 6 | E16: 28 | F16: 목 | G16: 0.79166667 | H16: 배병우의<대양을 향하여>를 위한<거문고,소리,피아노 그리고 춤> | I16: 공연 | J16: 대관 | K16: 대중 | L16: 행사 | M16: 소극장 | N16: 302 | O16: 무료 | P16: 0 | Q16: 239 | R16: =P16+Q16 | S16: 0 | T16: 215 | U16: =S16+T16
A17: 14 | B17: 11 | C17: 2012년 | D17: 6 | E17: 29 | F17: 금 | G17: 0.8125 | H17: 2012 여수엑스포 축하음악회 - 여수필하모닉오케스트라 제 24회 연주회 | I17: 공연 | J17: 대관 | K17: 순수 | L17: 클래식 | M17: 대극장 | N17: =948 | O17: 무료 | P17: 0 | Q17: 732 | R17: =P17+Q17 | S17: 0 | T17: 650 | U17: =S17+T17
A18: 소계 | B18: 11 | C18: 2012년 | D18: 6 | E18: 10 | N18: =SUM(N7:N17) | P18: =SUM(P7:P17) | Q18: =SUM(Q7:Q17) | R18: =SUM(R7:R17) | S18: =SUM(S7:S17) | T18: =SUM(T7:T17) | U18: =SUM(U7:U17) | V18: 11 | W18: 10 | X18: 4444 | Y18: 1751 | Z18: =X18+Y18
A19: 15 | B19: 1 | C19: 2012년 | D19: 7 | E19: 4 | F19: 수 | G19: 0.41666667 | H19: 제15회 대학생 국토대장정 출정식 | I19: 공연 | J19: 대관 | K19: 대중 | L19: 행사 | M19: 야외 | N19: 100 | O19: 무료 | P19: 0 | Q19: 100 | R19: =P19+Q19 | S19: 0 | T19: 100 | U19: =S19+T19
A20: 16 | B20: 2 | C20: 2012년 | D20: 7 | E20: 4 | F20: 수 | G20: 0.58333333 | H20: 제14회 지속가능발전전국대회 | I20: 공연 | J20: 대관 | K20: 대중 | L20: 행사 | M20: 대극장 | N20: 1021 | O20: 무료 | P20: 0 | Q20: 400 | R20: =P20+Q20 | S20: 0 | T20: 400 | U20: =S20+T20
A21: 17 | B21: 3 | C21: 2012년 | D21: 7 | E21: 5 | F21: 목 | G21: 0.58333333 | H21: 제14회 지속가능발전전국대회 | I21: 공연 | J21: 대관 | K21: 대중 | L21: 행사 | M21: 소극장 | N21: 302 | O21: 무료 | P21: 0 | Q21: 200 | R21: =P21+Q21 | S21: 0 | T21: 200 | U21: =S21+T21
A22: 18 | B22: 4 | C22: 2012년 | D22: 7 | E22: 6 | F22: 금 | G22: 0.58333333 | H22: 제14회 지속가능발전전국대회 | I22: 공연 | J22: 대관 | K22: 대중 | L22: 행사 | M22: 대극장 | N22: 1021 | O22: 무료 | P22: 0 | Q22: 400 | R22: =P22+Q22 | S22: 0 | T22: 400 | U22: =S22+T22
A23: 19 | B23: 5 | C23: 2012년 | D23: 7 | E23: 7 | F23: 토 | G23: 0.70833333 | H23: [2012 여수 엑스포 축하기념] 뉴욕 주립 청소년 오케스트라 (Empire State Youth Orchestra) 초청 연주회 | I23: 공연 | J23: 대관 | K23: 순수 | L23: 클래식 | M23: 대극장 | N23: =948 | O23: 무료 | P23: 0 | Q23: 716 | R23: =P23+Q23 | S23: 0 | T23: 688 | U23: =S23+T23
A24: 20 | B24: 6 | C24: 2012년 | D24: 7 | E24: 12 | F24: 목 | G24: 0.8125 | H24: 창작가무악극<오돌래> | I24: 공연 | J24: 대관 | K24: 복합 | L24: 창극 | M24: 대극장 | N24: =948 | O24: 유료 | P24: 441 | Q24: 82 | R24: =P24+Q24 | S24: 473 | T24: 71 | U24: =S24+T24
A25: 21 | B25: 7 | C25: 2012년 | D25: 7 | E25: 13 | F25: 금 | G25: 0.8125 | H25: 창작가무악극<오돌래> | I25: 공연 | J25: 대관 | K25: 복합 | L25: 창극 | M25: 대극장 | N25: =948 | O25: 유료 | P25: 539 | Q25: 57 | R25: =P25+Q25 | S25: 471 | T25: 55 | U25: =S25+T25
A26: 22 | B26: 8 | C26: 2012년 | D26: 7 | E26: 14 | F26: 토 | G26: 0.70833333 | H26: 창작가무악극<오돌래> | I26: 공연 | J26: 대관 | K26: 복합 | L26: 창극 | M26: 대극장 | N26: =948 | O26: 유료 | P26: 552 | Q26: 94 | R26: =P26+Q26 | S26: 471 | T26: 83 | U26: =S26+T26
A27: 23 | B27: 9 | C27: 2012년 | D27: 7 | E27: 21 | F27: 토 | G27: 0.70833333 | H27: 광주시립무용단 한국창작발레 성웅 이순신 | I27: 공연 | J27: 대관 | K27: 순수 | L27: 무용 | M27: 대극장 | N27: =948 | O27: 무료 | P27: 0 | Q27: 575 | R27: =P27+Q27 | S27: 0 | T27: 499 | U27: =S27+T27
A28: 24 | B28: 10 | C28: 2012년 | D28: 7 | E28: 27 | F28: 금 | G28: 0.79166667 | H28: 전남도립국악단 판페라 "이순신" - 민초와 함께 부르는 의로운 함성 | I28: 공연 | J28: 대관 | K28: 복합 | L28: 오페라 | M28: 대극장 | N28: =948 | O28: 유료 | P28: 604 | Q28: 254 | R28: =P28+Q28 | S28: 585 | T28: 240 | U28: =S28+T28
A29: 25 | B29: 11 | C29: 2012년 | D29: 7 | E29: 28 | F29: 토 | G29: 0.75 | H29: 유럽거장들과 함께하는 Music Travel | I29: 공연 | J29: 대관 | K29: 순수 | L29: 클래식 | M29: 소극장 | N29: 302 | O29: 유료 | P29: 150 | Q29: 45 | R29: =P29+Q29 | S29: 137 | T29: 34 | U29: =S29+T29
A30: 26 | B30: 12 | C30: 2012년 | D30: 7 | E30: 31 | F30: 화 | G30: 0.79166667 | H30: 2012 여수국제장애인EXPO | I30: 공연 | J30: 대관 | K30: 대중 | L30: 행사 | M30: 대극장 | N30: =948 | O30: 무료 | P30: 0 | Q30: 520 | R30: =P30+Q30 | S30: 0 | T30: 520 | U30: =S30+T30
